Workbook

Sheet VENDA MES
A1: SKU | B1: QUANTIDADE_TOTAL_MES_SET | E1: SKU | F1: QUANTIDADE_TOTAL_MES_OUT | H1: SKU | I1: QUANTIDADE_TOTAL_MES_NOV | K1: SKU | L1: QUANTIDADE_TOTAL_MES_DEZ
A2: SKU0001 | B2: 35 | C2: =B2*5 -> 175 | E2: SKU0001 | F2: 25 | H2: SKU0001 | I2: 43 | K2: SKU0001 | L2: 72
A3: SKU0002 | B3: 20 | C3: =B3*5 -> 100 | E3: SKU0002 | F3: 37 | H3: SKU0002 | I3: 44 | K3: SKU0002 | L3: 92
A4: SKU0003 | B4: 42 | C4: =B4*5 -> 210 | E4: SKU0003 | F4: 38 | H4: SKU0003 | I4: 41 | K4: SKU0003 | L4: 102
A5: SKU0004 | B5: 11 | C5: =B5*5 -> 55 | E5: SKU0004 | F5: 29 | H5: SKU0004 | I5: 31 | K5: SKU0004 | L5: 63
A6: SKU0005 | B6: 10 | C6: =B6*5 -> 50 | E6: SKU0005 | F6: 79 | H6: SKU0005 | I6: 35 | K6: SKU0005 | L6: 88
A7: SKU0007 | B7: 29 | C7: =B7*5 -> 145 | E7: SKU0006 | F7: 24 | H7: SKU0006 | I7: 62 | K7: SKU0006 | L7: 50
A8: SKU0008 | B8: 30 | C8: =B8*5 -> 150 | E8: SKU0007 | F8: 22 | H8: SKU0007 | I8: 29 | K8: SKU0007 | L8: 61
A9: SKU0009 | B9: 27 | C9: =B9*5 -> 135 | E9: SKU0008 | F9: 27 | H9: SKU0008 | I9: 53 | K9: SKU0008 | L9: 71
A10: SKU0010 | B10: 24 | C10: =B10*5 -> 120 | E10: SKU0009 | F10: 41 | H10: SKU0009 | I10: 53 | K10: SKU0009 | L10: 26
A11: SKU0011 | B11: 13 | C11: =B11*5 -> 65 | E11: SKU0010 | F11: 66 | H11: SKU0010 | I11: 65 | K11: SKU0010 | L11: 101
A12: SKU0012 | B12: 16 | C12: =B12*5 -> 80 | E12: SKU0011 | F12: 29 | H12: SKU0011 | I12: 67 | K12: SKU0011 | L12: 35
A13: SKU0013 | B13: 38 | C13: =B13*5 -> 190 | E13: SKU0012 | F13: 21 | H13: SKU0012 | I13: 43 | K13: SKU0012 | L13: 58
... A998: SKU1097 | B998: 21 | C998: =B998*5 -> 105 | E998: SKU1002 | F998: 37 | H998: SKU0997 | I998: 22 | K998: SKU0999 | L998: 75
A999: SKU1098 | B999: 23 | C999: =B999*5 -> 115 | H999: SKU0998 | I999: 59 | K999: SKU1000 | L999: 74
A1000: SKU1099 | B1000: 12 | C1000: =B1000*5 -> 60 | H1000: SKU0999 | I1000: 19 | K1000: SKU1001 | L1000: 66
A1001: SKU1100 | B1001: 20 | C1001: =B1001*5 -> 100 | H1001: SKU1000 | I1001: 70 | K1001: SKU1002 | L1001: 71
H1002: SKU1001 | I1002: 72
H1003: SKU1002 | I1003: 37
H1004: SKU1003 | I1004: 62
H1005: SKU1004 | I1005: 46
H1006: SKU1005 | I1006: 51
H1007: SKU1006 | I1007: 37
H1008: SKU1007 | I1008: 25
H1009: SKU1008 | I1009: 34
H1010: SKU1009 | I1010: 44
H1011: SKU1010 | I1011: 63
H1012: SKU1011 | I1012: 64
H1013: SKU1012 | I1013: 73
... H1101: SKU1100 | I1101: 17

Sheet MEDIDAS
A2: SKU | B2: DEMANDA_DIARIA_SETEMBRO | C2: DEMANDA_DIARIA_OUTUBRO | D2: DEMANDA_DIARIA_NOVEMBRO | E2: DEMANDA_DIARIA_DEZEMBRO | H2: SKU | I2: Custo_Setembro | J2: Custo_outubro | K2: Custo_novembro | L2: Custo_dezembro
A3: SKU0001 | B3: =_xlfn.XLOOKUP(A3,'VENDA MES'!A:A,'VENDA MES'!B:B,"0",0)/30 -> 1.1666667 | C3: =SUM(_xlfn.XLOOKUP(A3,'VENDA MES'!A:A,'VENDA MES'!B:B,0,0),_xlfn.XLOOKUP(A3,'VENDA MES'!E:E,'VENDA MES'!F:F,"0",0))/60 -> 1 | D3: =SUM(_xlfn.XLOOKUP(A3,'VENDA MES'!A:A,'VENDA MES'!B:B,"0",0),_xlfn.XLOOKUP(MEDIDAS!A3,'VENDA MES'!E:E,'VENDA MES'!F:F,"0",0),_xlfn.XLOOKUP(A3,'VENDA MES'!H:H,'VENDA MES'!I:I,"0",0))/90 -> 1.1444444 | E3: =SUM(_xlfn.XLOOKUP(A3,'VENDA MES'!A:A,'VENDA MES'!B:B,"0",0),_xlfn.XLOOKUP(MEDIDAS!A3,'VENDA MES'!E:E,'VENDA MES'!F:F,"0",0),_xlfn.XLOOKUP(MEDIDAS!A3,'VENDA MES'!H:H,'VENDA MES'!I:I,"0",0),_xlfn.XLOOKUP(MEDIDAS!A3,'VENDA MES'!K:K,'VENDA MES'!L:L,"0",0))/120 -> 1.4583333 | H3: SKU0001 | I3: 24 | J3: 24 | K3: 48 | L3: 60
A4: SKU0002 | B4: =_xlfn.XLOOKUP(A4,'VENDA MES'!A:A,'VENDA MES'!B:B,"0",0)/30 -> 0.66666667 | C4: =SUM(_xlfn.XLOOKUP(A4,'VENDA MES'!A:A,'VENDA MES'!B:B,0,0),_xlfn.XLOOKUP(A4,'VENDA MES'!E:E,'VENDA MES'!F:F,"0",0))/60 -> 0.95 | D4: =SUM(_xlfn.XLOOKUP(A4,'VENDA MES'!A:A,'VENDA MES'!B:B,"0",0),_xlfn.XLOOKUP(MEDIDAS!A4,'VENDA MES'!E:E,'VENDA MES'!F:F,"0",0),_xlfn.XLOOKUP(A4,'VENDA MES'!H:H,'VENDA MES'!I:I,"0",0))/90 -> 1.1222222 | E4: =SUM(_xlfn.XLOOKUP(A4,'VENDA MES'!A:A,'VENDA MES'!B:B,"0",0),_xlfn.XLOOKUP(MEDIDAS!A4,'VENDA MES'!E:E,'VENDA MES'!F:F,"0",0),_xlfn.XLOOKUP(MEDIDAS!A4,'VENDA MES'!H:H,'VENDA MES'!I:I,"0",0),_xlfn.XLOOKUP(MEDIDAS!A4,'VENDA MES'!K:K,'VENDA MES'!L:L,"0",0))/120 -> 1.6083333 | H4: SKU0002 | I4: 24 | J4: 24 | K4: 48 | L4: 60
A5: SKU0003 | B5: =_xlfn.XLOOKUP(A5,'VENDA MES'!A:A,'VENDA MES'!B:B,"0",0)/30 -> 1.4 | C5: =SUM(_xlfn.XLOOKUP(A5,'VENDA MES'!A:A,'VENDA MES'!B:B,0,0),_xlfn.XLOOKUP(A5,'VENDA MES'!E:E,'VENDA MES'!F:F,"0",0))/60 -> 1.3333333 | D5: =SUM(_xlfn.XLOOKUP(A5,'VENDA MES'!A:A,'VENDA MES'!B:B,"0",0),_xlfn.XLOOKUP(MEDIDAS!A5,'VENDA MES'!E:E,'VENDA MES'!F:F,"0",0),_xlfn.XLOOKUP(A5,'VENDA MES'!H:H,'VENDA MES'!I:I,"0",0))/90 -> 1.3444444 | E5: =SUM(_xlfn.XLOOKUP(A5,'VENDA MES'!A:A,'VENDA MES'!B:B,"0",0),_xlfn.XLOOKUP(MEDIDAS!A5,'VENDA MES'!E:E,'VENDA MES'!F:F,"0",0),_xlfn.XLOOKUP(MEDIDAS!A5,'VENDA MES'!H:H,'VENDA MES'!I:I,"0",0),_xlfn.XLOOKUP(MEDIDAS!A5,'VENDA MES'!K:K,'VENDA MES'!L:L,"0",0))/120 -> 1.8583333 | H5: SKU0003 | I5: 24 | J5: 24 | K5: 48 | L5: 60
A6: SKU0004 | B6: =_xlfn.XLOOKUP(A6,'VENDA MES'!A:A,'VENDA MES'!B:B,"0",0)/30 -> 0.36666667 | C6: =SUM(_xlfn.XLOOKUP(A6,'VENDA MES'!A:A,'VENDA MES'!B:B,0,0),_xlfn.XLOOKUP(A6,'VENDA MES'!E:E,'VENDA MES'!F:F,"0",0))/60 -> 0.66666667 | D6: =SUM(_xlfn.XLOOKUP(A6,'VENDA MES'!A:A,'VENDA MES'!B:B,"0",0),_xlfn.XLOOKUP(MEDIDAS!A6,'VENDA MES'!E:E,'VENDA MES'!F:F,"0",0),_xlfn.XLOOKUP(A6,'VENDA MES'!H:H,'VENDA MES'!I:I,"0",0))/90 -> 0.78888889 | E6: =SUM(_xlfn.XLOOKUP(A6,'VENDA MES'!A:A,'VENDA MES'!B:B,"0",0),_xlfn.XLOOKUP(MEDIDAS!A6,'VENDA MES'!E:E,'VENDA MES'!F:F,"0",0),_xlfn.XLOOKUP(MEDIDAS!A6,'VENDA MES'!H:H,'VENDA MES'!I:I,"0",0),_xlfn.XLOOKUP(MEDIDAS!A6,'VENDA MES'!K:K,'VENDA MES'!L:L,"0",0))/120 -> 1.1166667 | H6: SKU0004 | I6: 24 | J6: 24 | K6: 48 | L6: 60
A7: SKU0005 | B7: =_xlfn.XLOOKUP(A7,'VENDA MES'!A:A,'VENDA MES'!B:B,"0",0)/30 -> 0.33333333 | C7: =SUM(_xlfn.XLOOKUP(A7,'VENDA MES'!A:A,'VENDA MES'!B:B,0,0),_xlfn.XLOOKUP(A7,'VENDA MES'!E:E,'VENDA MES'!F:F,"0",0))/60 -> 1.4833333 | D7: =SUM(_xlfn.XLOOKUP(A7,'VENDA MES'!A:A,'VENDA MES'!B:B,"0",0),_xlfn.XLOOKUP(MEDIDAS!A7,'VENDA MES'!E:E,'VENDA MES'!F:F,"0",0),_xlfn.XLOOKUP(A7,'VENDA MES'!H:H,'VENDA MES'!I:I,"0",0))/90 -> 1.3777778 | E7: =SUM(_xlfn.XLOOKUP(A7,'VENDA MES'!A:A,'VENDA MES'!B:B,"0",0),_xlfn.XLOOKUP(MEDIDAS!A7,'VENDA MES'!E:E,'VENDA MES'!F:F,"0",0),_xlfn.XLOOKUP(MEDIDAS!A7,'VENDA MES'!H:H,'VENDA MES'!I:I,"0",0),_xlfn.XLOOKUP(MEDIDAS!A7,'VENDA MES'!K:K,'VENDA MES'!L:L,"0",0))/120 -> 1.7666667 | H7: SKU0005 | I7: 24 | J7: 24 | K7: 48 | L7: 60
A8: SKU0006 | B8: =_xlfn.XLOOKUP(A8,'VENDA MES'!A:A,'VENDA MES'!B:B,"0",0)/30 -> 0 | C8: =SUM(_xlfn.XLOOKUP(A8,'VENDA MES'!A:A,'VENDA MES'!B:B,0,0),_xlfn.XLOOKUP(A8,'VENDA MES'!E:E,'VENDA MES'!F:F,"0",0))/60 -> 0.4 | D8: =SUM(_xlfn.XLOOKUP(A8,'VENDA MES'!A:A,'VENDA MES'!B:B,"0",0),_xlfn.XLOOKUP(MEDIDAS!A8,'VENDA MES'!E:E,'VENDA MES'!F:F,"0",0),_xlfn.XLOOKUP(A8,'VENDA MES'!H:H,'VENDA MES'!I:I,"0",0))/90 -> 0.95555556 | E8: =SUM(_xlfn.XLOOKUP(A8,'VENDA MES'!A:A,'VENDA MES'!B:B,"0",0),_xlfn.XLOOKUP(MEDIDAS!A8,'VENDA MES'!E:E,'VENDA MES'!F:F,"0",0),_xlfn.XLOOKUP(MEDIDAS!A8,'VENDA MES'!H:H,'VENDA MES'!I:I,"0",0),_xlfn.XLOOKUP(MEDIDAS!A8,'VENDA MES'!K:K,'VENDA MES'!L:L,"0",0))/120 -> 1.1333333 | H8: SKU0006 | I8: 24 | J8: 24 | K8: 48 | L8: 60
A9: SKU0007 | B9: =_xlfn.XLOOKUP(A9,'VENDA MES'!A:A,'VENDA MES'!B:B,"0",0)/30 -> 0.96666667 | C9: =SUM(_xlfn.XLOOKUP(A9,'VENDA MES'!A:A,'VENDA MES'!B:B,0,0),_xlfn.XLOOKUP(A9,'VENDA MES'!E:E,'VENDA MES'!F:F,"0",0))/60 -> 0.85 | D9: =SUM(_xlfn.XLOOKUP(A9,'VENDA MES'!A:A,'VENDA MES'!B:B,"0",0),_xlfn.XLOOKUP(MEDIDAS!A9,'VENDA MES'!E:E,'VENDA MES'!F:F,"0",0),_xlfn.XLOOKUP(A9,'VENDA MES'!H:H,'VENDA MES'!I:I,"0",0))/90 -> 0.88888889 | E9: =SUM(_xlfn.XLOOKUP(A9,'VENDA MES'!A:A,'VENDA MES'!B:B,"0",0),_xlfn.XLOOKUP(MEDIDAS!A9,'VENDA MES'!E:E,'VENDA MES'!F:F,"0",0),_xlfn.XLOOKUP(MEDIDAS!A9,'VENDA MES'!H:H,'VENDA MES'!I:I,"0",0),_xlfn.XLOOKUP(MEDIDAS!A9,'VENDA MES'!K:K,'VENDA MES'!L:L,"0",0))/120 -> 1.175 | H9: SKU0007 | I9: 24 | J9: 24 | K9: 48 | L9: 60
A10: SKU0008 | B10: =_xlfn.XLOOKUP(A10,'VENDA MES'!A:A,'VENDA MES'!B:B,"0",0)/30 -> 1 | C10: =SUM(_xlfn.XLOOKUP(A10,'VENDA MES'!A:A,'VENDA MES'!B:B,0,0),_xlfn.XLOOKUP(A10,'VENDA MES'!E:E,'VENDA MES'!F:F,"0",0))/60 -> 0.95 | D10: =SUM(_xlfn.XLOOKUP(A10,'VENDA MES'!A:A,'VENDA MES'!B:B,"0",0),_xlfn.XLOOKUP(MEDIDAS!A10,'VENDA MES'!E:E,'VENDA MES'!F:F,"0",0),_xlfn.XLOOKUP(A10,'VENDA MES'!H:H,'VENDA MES'!I:I,"0",0))/90 -> 1.2222222 | E10: =SUM(_xlfn.XLOOKUP(A10,'VENDA MES'!A:A,'VENDA MES'!B:B,"0",0),_xlfn.XLOOKUP(MEDIDAS!A10,'VENDA MES'!E:E,'VENDA MES'!F:F,"0",0),_xlfn.XLOOKUP(MEDIDAS!A10,'VENDA MES'!H:H,'VENDA MES'!I:I,"0",0),_xlfn.XLOOKUP(MEDIDAS!A10,'VENDA MES'!K:K,'VENDA MES'!L:L,"0",0))/120 -> 1.5083333 | H10: SKU0008 | I10: 24 | J10: 24 | K10: 48 | L10: 60
A11: SKU0009 | B11: =_xlfn.XLOOKUP(A11,'VENDA MES'!A:A,'VENDA MES'!B:B,"0",0)/30 -> 0.9 | C11: =SUM(_xlfn.XLOOKUP(A11,'VENDA MES'!A:A,'VENDA MES'!B:B,0,0),_xlfn.XLOOKUP(A11,'VENDA MES'!E:E,'VENDA MES'!F:F,"0",0))/60 -> 1.1333333 | D11: =SUM(_xlfn.XLOOKUP(A11,'VENDA MES'!A:A,'VENDA MES'!B:B,"0",0),_xlfn.XLOOKUP(MEDIDAS!A11,'VENDA MES'!E:E,'VENDA MES'!F:F,"0",0),_xlfn.XLOOKUP(A11,'VENDA MES'!H:H,'VENDA MES'!I:I,"0",0))/90 -> 1.3444444 | E11: =SUM(_xlfn.XLOOKUP(A11,'VENDA MES'!A:A,'VENDA MES'!B:B,"0",0),_xlfn.XLOOKUP(MEDIDAS!A11,'VENDA MES'!E:E,'VENDA MES'!F:F,"0",0),_xlfn.XLOOKUP(MEDIDAS!A11,'VENDA MES'!H:H,'VENDA MES'!I:I,"0",0),_xlfn.XLOOKUP(MEDIDAS!A11,'VENDA MES'!K:K,'VENDA MES'!L:L,"0",0))/120 -> 1.225 | H11: SKU0009 | I11: 24 | J11: 24 | K11: 48 | L11: 60
A12: SKU0010 | B12: =_xlfn.XLOOKUP(A12,'VENDA MES'!A:A,'VENDA MES'!B:B,"0",0)/30 -> 0.8 | C12: =SUM(_xlfn.XLOOKUP(A12,'VENDA MES'!A:A,'VENDA MES'!B:B,0,0),_xlfn.XLOOKUP(A12,'VENDA MES'!E:E,'VENDA MES'!F:F,"0",0))/60 -> 1.5 | D12: =SUM(_xlfn.XLOOKUP(A12,'VENDA MES'!A:A,'VENDA MES'!B:B,"0",0),_xlfn.XLOOKUP(MEDIDAS!A12,'VENDA MES'!E:E,'VENDA MES'!F:F,"0",0),_xlfn.XLOOKUP(A12,'VENDA MES'!H:H,'VENDA MES'!I:I,"0",0))/90 -> 1.7222222 | E12: =SUM(_xlfn.XLOOKUP(A12,'VENDA MES'!A:A,'VENDA MES'!B:B,"0",0),_xlfn.XLOOKUP(MEDIDAS!A12,'VENDA MES'!E:E,'VENDA MES'!F:F,"0",0),_xlfn.XLOOKUP(MEDIDAS!A12,'VENDA MES'!H:H,'VENDA MES'!I:I,"0",0),_xlfn.XLOOKUP(MEDIDAS!A12,'VENDA MES'!K:K,'VENDA MES'!L:L,"0",0))/120 -> 2.1333333 | H12: SKU0010 | I12: 24 | J12: 24 | K12: 48 | L12: 60
A13: SKU0011 | B13: =_xlfn.XLOOKUP(A13,'VENDA MES'!A:A,'VENDA MES'!B:B,"0",0)/30 -> 0.43333333 | C13: =SUM(_xlfn.XLOOKUP(A13,'VENDA MES'!A:A,'VENDA MES'!B:B,0,0),_xlfn.XLOOKUP(A13,'VENDA MES'!E:E,'VENDA MES'!F:F,"0",0))/60 -> 0.7 | D13: =SUM(_xlfn.XLOOKUP(A13,'VENDA MES'!A:A,'VENDA MES'!B:B,"0",0),_xlfn.XLOOKUP(MEDIDAS!A13,'VENDA MES'!E:E,'VENDA MES'!F:F,"0",0),_xlfn.XLOOKUP(A13,'VENDA MES'!H:H,'VENDA MES'!I:I,"0",0))/90 -> 1.2111111 | E13: =SUM(_xlfn.XLOOKUP(A13,'VENDA MES'!A:A,'VENDA MES'!B:B,"0",0),_xlfn.XLOOKUP(MEDIDAS!A13,'VENDA MES'!E:E,'VENDA MES'!F:F,"0",0),_xlfn.XLOOKUP(MEDIDAS!A13,'VENDA MES'!H:H,'VENDA MES'!I:I,"0",0),_xlfn.XLOOKUP(MEDIDAS!A13,'VENDA MES'!K:K,'VENDA MES'!L:L,"0",0))/120 -> 1.2 | H13: SKU0011 | I13: 5 | J13: 5 | K13: 10 | L13: 12.5
A14: SKU0012 | B14: =_xlfn.XLOOKUP(A14,'VENDA MES'!A:A,'VENDA MES'!B:B,"0",0)/30 -> 0.53333333 | C14: =SUM(_xlfn.XLOOKUP(A14,'VENDA MES'!A:A,'VENDA MES'!B:B,0,0),_xlfn.XLOOKUP(A14,'VENDA MES'!E:E,'VENDA MES'!F:F,"0",0))/60 -> 0.61666667 | D14: =SUM(_xlfn.XLOOKUP(A14,'VENDA MES'!A:A,'VENDA MES'!B:B,"0",0),_xlfn.XLOOKUP(MEDIDAS!A14,'VENDA MES'!E:E,'VENDA MES'!F:F,"0",0),_xlfn.XLOOKUP(A14,'VENDA MES'!H:H,'VENDA MES'!I:I,"0",0))/90 -> 0.88888889 | E14: =SUM(_xlfn.XLOOKUP(A14,'VENDA MES'!A:A,'VENDA MES'!B:B,"0",0),_xlfn.XLOOKUP(MEDIDAS!A14,'VENDA MES'!E:E,'VENDA MES'!F:F,"0",0),_xlfn.XLOOKUP(MEDIDAS!A14,'VENDA MES'!H:H,'VENDA MES'!I:I,"0",0),_xlfn.XLOOKUP(MEDIDAS!A14,'VENDA MES'!K:K,'VENDA MES'!L:L,"0",0))/120 -> 1.15 | H14: SKU0012 | I14: 5 | J14: 5 | K14: 10 | L14: 12.5
... A1102: SKU1100 | B1102: =_xlfn.XLOOKUP(A1102,'VENDA MES'!A:A,'VENDA MES'!B:B,"0",0)/30 -> 0.66666667 | C1102: =SUM(_xlfn.XLOOKUP(A1102,'VENDA MES'!A:A,'VENDA MES'!B:B,0,0),_xlfn.XLOOKUP(A1102,'VENDA MES'!E:E,'VENDA MES'!F:F,"0",0))/60 -> 0.33333333 | D1102: =SUM(_xlfn.XLOOKUP(A1102,'VENDA MES'!A:A,'VENDA MES'!B:B,"0",0),_xlfn.XLOOKUP(MEDIDAS!A1102,'VENDA MES'!E:E,'VENDA MES'!F:F,"0",0),_xlfn.XLOOKUP(A1102,'VENDA MES'!H:H,'VENDA MES'!I:I,"0",0))/90 -> 0.41111111 | E1102: =SUM(_xlfn.XLOOKUP(A1102,'VENDA MES'!A:A,'VENDA MES'!B:B,"0",0),_xlfn.XLOOKUP(MEDIDAS!A1102,'VENDA MES'!E:E,'VENDA MES'!F:F,"0",0),_xlfn.XLOOKUP(MEDIDAS!A1102,'VENDA MES'!H:H,'VENDA MES'!I:I,"0",0),_xlfn.XLOOKUP(MEDIDAS!A1102,'VENDA MES'!K:K,'VENDA MES'!L:L,"0",0))/120 -> 0.30833333 | H1102: SKU1100 | I1102: 20 | J1102: 20 | K1102: 40 | L1102: 50

Sheet ESTOQUE SETEMBRO
A1: SKU | B1: SKU_DESCRICAO | C1: ESTOQUE_DE_SEGURANCA | D1: ESTOQUE_INICIAL | E1: ABASTECIMENTO | F1: ESTOQUE_ATUAL | G1: CUSTO_UNITARIO_M-1 | H1: CUSTO_UNITARIO_M0 | I1: CATEGORIA | J1: CUSTO_TOTAL_POR_ITEM | K1: ESTOQUE_MINIMO | L1: PONTO_DE_REPOSICAO | M1: CATEGORIA_DE_ESTOQUE | N1: ULTIMO_ABASTECIMENTO_SETEMBRO | O1: ESTOQUE_MES
A2: SKU0001 | B2: Fone de Ouvido Bluetooth | C2: =3.09*1*7 -> 21.63 | D2: 38.5 | E2: =IF(Tabela1[[#This Row],[ESTOQUE_INICIAL]]>=150,Tabela1[[#This Row],[ESTOQUE_INICIAL]]*0,IF(Tabela1[[#This Row],[ESTOQUE_INICIAL]]=0,SUM(Tabela1[[#This Row],[ESTOQUE_INICIAL]],150),Tabela1[[#This Row],[ESTOQUE_INICIAL]]*5)) -> 192.5 | F2: =SUM(E2,D2) -> 231 | G2: 26.4 | H2: 24 | I2: Eletrônicos | J2: =Tabela1[[#This Row],[ESTOQUE_INICIAL]]*Tabela1[[#This Row],[CUSTO_UNITARIO_M-1]]+Tabela1[[#This Row],[ABASTECIMENTO]]*Tabela1[[#This Row],[CUSTO_UNITARIO_M0]] -> 5636.4 | K2: =_xlfn.XLOOKUP(A2,MEDIDAS!A:A,MEDIDAS!B:B,"0",0)*5 -> 5.8333333 | L2: =SUM(K2,(_xlfn.XLOOKUP(A2,MEDIDAS!A:A,MEDIDAS!B:B,"0",0)*5)) -> 11.666667 | M2: =IF(F2>=SUM(L2,_xlfn.XLOOKUP(A2,'ESTOQUE SETEMBRO'!A:A,'ESTOQUE SETEMBRO'!F:F,,0))/2*1.2,"OVER",IF(F2<=SUM(L2,_xlfn.XLOOKUP(A2,'ESTOQUE SETEMBRO'!A:A,'ESTOQUE SETEMBRO'!F:F,,0))/2*1.1,"IDEAL","OUT")) -> OVER | N2: =IF('ESTOQUE SETEMBRO'!$E2>=0,"setembro","sem abastecimento") -> setembro | O2: 45536
A3: SKU0002 | B3: Fone de Ouvido Bluetooth | C3: =3.09*1*7 -> 21.63 | D3: 22 | E3: =IF(Tabela1[[#This Row],[ESTOQUE_INICIAL]]>=150,Tabela1[[#This Row],[ESTOQUE_INICIAL]]*0,IF(Tabela1[[#This Row],[ESTOQUE_INICIAL]]=0,SUM(Tabela1[[#This Row],[ESTOQUE_INICIAL]],150),Tabela1[[#This Row],[ESTOQUE_INICIAL]]*5)) -> 110 | F3: =SUM(E3,D3) -> 132 | G3: 26.4 | H3: 24 | I3: Eletrônicos | J3: =Tabela1[[#This Row],[ESTOQUE_INICIAL]]*Tabela1[[#This Row],[CUSTO_UNITARIO_M-1]]+Tabela1[[#This Row],[ABASTECIMENTO]]*Tabela1[[#This Row],[CUSTO_UNITARIO_M0]] -> 3220.8 | K3: =_xlfn.XLOOKUP(A3,MEDIDAS!A:A,MEDIDAS!B:B,"0",0)*5 -> 3.3333333 | L3: =SUM(K3,(_xlfn.XLOOKUP(A3,MEDIDAS!A:A,MEDIDAS!B:B,"0",0)*5)) -> 6.6666667 | M3: =IF(F3>=SUM(L3,_xlfn.XLOOKUP(A3,'ESTOQUE SETEMBRO'!A:A,'ESTOQUE SETEMBRO'!F:F,,0))/2*1.2,"OVER",IF(F3<=SUM(L3,_xlfn.XLOOKUP(A3,'ESTOQUE SETEMBRO'!A:A,'ESTOQUE SETEMBRO'!F:F,,0))/2*1.1,"IDEAL","OUT")) -> OVER | N3: =IF('ESTOQUE SETEMBRO'!$E3>=0,"setembro","sem abastecimento") -> setembro | O3: 45536
A4: SKU0003 | B4: Fone de Ouvido Bluetooth | C4: =3.09*1*7 -> 21.63 | D4: 46.2 | E4: =IF(Tabela1[[#This Row],[ESTOQUE_INICIAL]]>=150,Tabela1[[#This Row],[ESTOQUE_INICIAL]]*0,IF(Tabela1[[#This Row],[ESTOQUE_INICIAL]]=0,SUM(Tabela1[[#This Row],[ESTOQUE_INICIAL]],150),Tabela1[[#This Row],[ESTOQUE_INICIAL]]*5)) -> 231 | F4: =SUM(E4,D4) -> 277.2 | G4: 26.4 | H4: 24 | I4: Eletrônicos | J4: =Tabela1[[#This Row],[ESTOQUE_INICIAL]]*Tabela1[[#This Row],[CUSTO_UNITARIO_M-1]]+Tabela1[[#This Row],[ABASTECIMENTO]]*Tabela1[[#This Row],[CUSTO_UNITARIO_M0]] -> 6763.68 | K4: =_xlfn.XLOOKUP(A4,MEDIDAS!A:A,MEDIDAS!B:B,"0",0)*5 -> 7 | L4: =SUM(K4,(_xlfn.XLOOKUP(A4,MEDIDAS!A:A,MEDIDAS!B:B,"0",0)*5)) -> 14 | M4: =IF(F4>=SUM(L4,_xlfn.XLOOKUP(A4,'ESTOQUE SETEMBRO'!A:A,'ESTOQUE SETEMBRO'!F:F,,0))/2*1.2,"OVER",IF(F4<=SUM(L4,_xlfn.XLOOKUP(A4,'ESTOQUE SETEMBRO'!A:A,'ESTOQUE SETEMBRO'!F:F,,0))/2*1.1,"IDEAL","OUT")) -> OVER | N4: =IF('ESTOQUE SETEMBRO'!$E4>=0,"setembro","sem abastecimento") -> setembro | O4: 45536
A5: SKU0004 | B5: Fone de Ouvido Bluetooth | C5: =3.09*1*7 -> 21.63 | D5: 12.1 | E5: =IF(Tabela1[[#This Row],[ESTOQUE_INICIAL]]>=150,Tabela1[[#This Row],[ESTOQUE_INICIAL]]*0,IF(Tabela1[[#This Row],[ESTOQUE_INICIAL]]=0,SUM(Tabela1[[#This Row],[ESTOQUE_INICIAL]],150),Tabela1[[#This Row],[ESTOQUE_INICIAL]]*5)) -> 60.5 | F5: =SUM(E5,D5) -> 72.6 | G5: 26.4 | H5: 24 | I5: Eletrônicos | J5: =Tabela1[[#This Row],[ESTOQUE_INICIAL]]*Tabela1[[#This Row],[CUSTO_UNITARIO_M-1]]+Tabela1[[#This Row],[ABASTECIMENTO]]*Tabela1[[#This Row],[CUSTO_UNITARIO_M0]] -> 1771.44 | K5: =_xlfn.XLOOKUP(A5,MEDIDAS!A:A,MEDIDAS!B:B,"0",0)*5 -> 1.8333333 | L5: =SUM(K5,(_xlfn.XLOOKUP(A5,MEDIDAS!A:A,MEDIDAS!B:B,"0",0)*5)) -> 3.6666667 | M5: =IF(F5>=SUM(L5,_xlfn.XLOOKUP(A5,'ESTOQUE SETEMBRO'!A:A,'ESTOQUE SETEMBRO'!F:F,,0))/2*1.2,"OVER",IF(F5<=SUM(L5,_xlfn.XLOOKUP(A5,'ESTOQUE SETEMBRO'!A:A,'ESTOQUE SETEMBRO'!F:F,,0))/2*1.1,"IDEAL","OUT")) -> OVER | N5: =IF('ESTOQUE SETEMBRO'!$E5>=0,"setembro","sem abastecimento") -> setembro | O5: 45536
A6: SKU0005 | B6: Fone de Ouvido Bluetooth | C6: =3.09*1*7 -> 21.63 | D6: 11 | E6: =IF(Tabela1[[#This Row],[ESTOQUE_INICIAL]]>=150,Tabela1[[#This Row],[ESTOQUE_INICIAL]]*0,IF(Tabela1[[#This Row],[ESTOQUE_INICIAL]]=0,SUM(Tabela1[[#This Row],[ESTOQUE_INICIAL]],150),Tabela1[[#This Row],[ESTOQUE_INICIAL]]*5)) -> 55 | F6: =SUM(E6,D6) -> 66 | G6: 26.4 | H6: 24 | I6: Eletrônicos | J6: =Tabela1[[#This Row],[ESTOQUE_INICIAL]]*Tabela1[[#This Row],[CUSTO_UNITARIO_M-1]]+Tabela1[[#This Row],[ABASTECIMENTO]]*Tabela1[[#This Row],[CUSTO_UNITARIO_M0]] -> 1610.4 | K6: =_xlfn.XLOOKUP(A6,MEDIDAS!A:A,MEDIDAS!B:B,"0",0)*5 -> 1.6666667 | L6: =SUM(K6,(_xlfn.XLOOKUP(A6,MEDIDAS!A:A,MEDIDAS!B:B,"0",0)*5)) -> 3.3333333 | M6: =IF(F6>=SUM(L6,_xlfn.XLOOKUP(A6,'ESTOQUE SETEMBRO'!A:A,'ESTOQUE SETEMBRO'!F:F,,0))/2*1.2,"OVER",IF(F6<=SUM(L6,_xlfn.XLOOKUP(A6,'ESTOQUE SETEMBRO'!A:A,'ESTOQUE SETEMBRO'!F:F,,0))/2*1.1,"IDEAL","OUT")) -> OVER | N6: =IF('ESTOQUE SETEMBRO'!$E6>=0,"setembro","sem abastecimento") -> setembro | O6: 45536
A7: SKU0006 | B7: Fone de Ouvido Bluetooth | C7: =3.09*1*7 -> 21.63 | D7: 0 | E7: =IF(Tabela1[[#This Row],[ESTOQUE_INICIAL]]>=150,Tabela1[[#This Row],[ESTOQUE_INICIAL]]*0,IF(Tabela1[[#This Row],[ESTOQUE_INICIAL]]=0,SUM(Tabela1[[#This Row],[ESTOQUE_INICIAL]],150),Tabela1[[#This Row],[ESTOQUE_INICIAL]]*5)) -> 150 | F7: =SUM(E7,D7) -> 150 | G7: 26.4 | H7: 24 | I7: Eletrônicos | J7: =Tabela1[[#This Row],[ESTOQUE_INICIAL]]*Tabela1[[#This Row],[CUSTO_UNITARIO_M-1]]+Tabela1[[#This Row],[ABASTECIMENTO]]*Tabela1[[#This Row],[CUSTO_UNITARIO_M0]] -> 3600 | K7: =_xlfn.XLOOKUP(A7,MEDIDAS!A:A,MEDIDAS!B:B,"0",0)*5 -> 0 | L7: =SUM(K7,(_xlfn.XLOOKUP(A7,MEDIDAS!A:A,MEDIDAS!B:B,"0",0)*5)) -> 0 | M7: =IF(F7>=SUM(L7,_xlfn.XLOOKUP(A7,'ESTOQUE SETEMBRO'!A:A,'ESTOQUE SETEMBRO'!F:F,,0))/2*1.2,"OVER",IF(F7<=SUM(L7,_xlfn.XLOOKUP(A7,'ESTOQUE SETEMBRO'!A:A,'ESTOQUE SETEMBRO'!F:F,,0))/2*1.1,"IDEAL","OUT")) -> OVER | N7: =IF('ESTOQUE SETEMBRO'!$E7>=0,"setembro","sem abastecimento") -> setembro | O7: 45536
A8: SKU0007 | B8: Fone de Ouvido Bluetooth | C8: =3.09*1*7 -> 21.63 | D8: 31.9 | E8: =IF(Tabela1[[#This Row],[ESTOQUE_INICIAL]]>=150,Tabela1[[#This Row],[ESTOQUE_INICIAL]]*0,IF(Tabela1[[#This Row],[ESTOQUE_INICIAL]]=0,SUM(Tabela1[[#This Row],[ESTOQUE_INICIAL]],150),Tabela1[[#This Row],[ESTOQUE_INICIAL]]*5)) -> 159.5 | F8: =SUM(E8,D8) -> 191.4 | G8: 26.4 | H8: 24 | I8: Eletrônicos | J8: =Tabela1[[#This Row],[ESTOQUE_INICIAL]]*Tabela1[[#This Row],[CUSTO_UNITARIO_M-1]]+Tabela1[[#This Row],[ABASTECIMENTO]]*Tabela1[[#This Row],[CUSTO_UNITARIO_M0]] -> 4670.16 | K8: =_xlfn.XLOOKUP(A8,MEDIDAS!A:A,MEDIDAS!B:B,"0",0)*5 -> 4.8333333 | L8: =SUM(K8,(_xlfn.XLOOKUP(A8,MEDIDAS!A:A,MEDIDAS!B:B,"0",0)*5)) -> 9.6666667 | M8: =IF(F8>=SUM(L8,_xlfn.XLOOKUP(A8,'ESTOQUE SETEMBRO'!A:A,'ESTOQUE SETEMBRO'!F:F,,0))/2*1.2,"OVER",IF(F8<=SUM(L8,_xlfn.XLOOKUP(A8,'ESTOQUE SETEMBRO'!A:A,'ESTOQUE SETEMBRO'!F:F,,0))/2*1.1,"IDEAL","OUT")) -> OVER | N8: =IF('ESTOQUE SETEMBRO'!$E8>=0,"setembro","sem abastecimento") -> setembro | O8: 45536
A9: SKU0008 | B9: Fone de Ouvido Bluetooth | C9: =3.09*1*7 -> 21.63 | D9: 33 | E9: =IF(Tabela1[[#This Row],[ESTOQUE_INICIAL]]>=150,Tabela1[[#This Row],[ESTOQUE_INICIAL]]*0,IF(Tabela1[[#This Row],[ESTOQUE_INICIAL]]=0,SUM(Tabela1[[#This Row],[ESTOQUE_INICIAL]],150),Tabela1[[#This Row],[ESTOQUE_INICIAL]]*5)) -> 165 | F9: =SUM(E9,D9) -> 198 | G9: 26.4 | H9: 24 | I9: Eletrônicos | J9: =Tabela1[[#This Row],[ESTOQUE_INICIAL]]*Tabela1[[#This Row],[CUSTO_UNITARIO_M-1]]+Tabela1[[#This Row],[ABASTECIMENTO]]*Tabela1[[#This Row],[CUSTO_UNITARIO_M0]] -> 4831.2 | K9: =_xlfn.XLOOKUP(A9,MEDIDAS!A:A,MEDIDAS!B:B,"0",0)*5 -> 5 | L9: =SUM(K9,(_xlfn.XLOOKUP(A9,MEDIDAS!A:A,MEDIDAS!B:B,"0",0)*5)) -> 10 | M9: =IF(F9>=SUM(L9,_xlfn.XLOOKUP(A9,'ESTOQUE SETEMBRO'!A:A,'ESTOQUE SETEMBRO'!F:F,,0))/2*1.2,"OVER",IF(F9<=SUM(L9,_xlfn.XLOOKUP(A9,'ESTOQUE SETEMBRO'!A:A,'ESTOQUE SETEMBRO'!F:F,,0))/2*1.1,"IDEAL","OUT")) -> OVER | N9: =IF('ESTOQUE SETEMBRO'!$E9>=0,"setembro","sem abastecimento") -> setembro | O9: 45536
A10: SKU0009 | B10: Fone de Ouvido Bluetooth | C10: =3.09*1*7 -> 21.63 | D10: 29.7 | E10: =IF(Tabela1[[#This Row],[ESTOQUE_INICIAL]]>=150,Tabela1[[#This Row],[ESTOQUE_INICIAL]]*0,IF(Tabela1[[#This Row],[ESTOQUE_INICIAL]]=0,SUM(Tabela1[[#This Row],[ESTOQUE_INICIAL]],150),Tabela1[[#This Row],[ESTOQUE_INICIAL]]*5)) -> 148.5 | F10: =SUM(E10,D10) -> 178.2 | G10: 26.4 | H10: 24 | I10: Eletrônicos | J10: =Tabela1[[#This Row],[ESTOQUE_INICIAL]]*Tabela1[[#This Row],[CUSTO_UNITARIO_M-1]]+Tabela1[[#This Row],[ABASTECIMENTO]]*Tabela1[[#This Row],[CUSTO_UNITARIO_M0]] -> 4348.08 | K10: =_xlfn.XLOOKUP(A10,MEDIDAS!A:A,MEDIDAS!B:B,"0",0)*5 -> 4.5 | L10: =SUM(K10,(_xlfn.XLOOKUP(A10,MEDIDAS!A:A,MEDIDAS!B:B,"0",0)*5)) -> 9 | M10: =IF(F10>=SUM(L10,_xlfn.XLOOKUP(A10,'ESTOQUE SETEMBRO'!A:A,'ESTOQUE SETEMBRO'!F:F,,0))/2*1.2,"OVER",IF(F10<=SUM(L10,_xlfn.XLOOKUP(A10,'ESTOQUE SETEMBRO'!A:A,'ESTOQUE SETEMBRO'!F:F,,0))/2*1.1,"IDEAL","OUT")) -> OVER | N10: =IF('ESTOQUE SETEMBRO'!$E10>=0,"setembro","sem abastecimento") -> setembro | O10: 45536
A11: SKU0010 | B11: Fone de Ouvido Bluetooth | C11: =3.09*1*7 -> 21.63 | D11: 26.4 | E11: =IF(Tabela1[[#This Row],[ESTOQUE_INICIAL]]>=150,Tabela1[[#This Row],[ESTOQUE_INICIAL]]*0,IF(Tabela1[[#This Row],[ESTOQUE_INICIAL]]=0,SUM(Tabela1[[#This Row],[ESTOQUE_INICIAL]],150),Tabela1[[#This Row],[ESTOQUE_INICIAL]]*5)) -> 132 | F11: =SUM(E11,D11) -> 158.4 | G11: 26.4 | H11: 24 | I11: Eletrônicos | J11: =Tabela1[[#This Row],[ESTOQUE_INICIAL]]*Tabela1[[#This Row],[CUSTO_UNITARIO_M-1]]+Tabela1[[#This Row],[ABASTECIMENTO]]*Tabela1[[#This Row],[CUSTO_UNITARIO_M0]] -> 3864.96 | K11: =_xlfn.XLOOKUP(A11,MEDIDAS!A:A,MEDIDAS!B:B,"0",0)*5 -> 4 | L11: =SUM(K11,(_xlfn.XLOOKUP(A11,MEDIDAS!A:A,MEDIDAS!B:B,"0",0)*5)) -> 8 | M11: =IF(F11>=SUM(L11,_xlfn.XLOOKUP(A11,'ESTOQUE SETEMBRO'!A:A,'ESTOQUE SETEMBRO'!F:F,,0))/2*1.2,"OVER",IF(F11<=SUM(L11,_xlfn.XLOOKUP(A11,'ESTOQUE SETEMBRO'!A:A,'ESTOQUE SETEMBRO'!F:F,,0))/2*1.1,"IDEAL","OUT")) -> OVER | N11: =IF('ESTOQUE SETEMBRO'!$E11>=0,"setembro","sem abastecimento") -> setembro | O11: 45536
A12: SKU0011 | B12: Capa para Celular | C12: =3.09*1*7 -> 21.63 | D12: 14.3 | E12: =IF(Tabela1[[#This Row],[ESTOQUE_INICIAL]]>=150,Tabela1[[#This Row],[ESTOQUE_INICIAL]]*0,IF(Tabela1[[#This Row],[ESTOQUE_INICIAL]]=0,SUM(Tabela1[[#This Row],[ESTOQUE_INICIAL]],150),Tabela1[[#This Row],[ESTOQUE_INICIAL]]*5)) -> 71.5 | F12: =SUM(E12,D12) -> 85.8 | G12: 5.5 | H12: 5 | I12: Acessórios | J12: =Tabela1[[#This Row],[ESTOQUE_INICIAL]]*Tabela1[[#This Row],[CUSTO_UNITARIO_M-1]]+Tabela1[[#This Row],[ABASTECIMENTO]]*Tabela1[[#This Row],[CUSTO_UNITARIO_M0]] -> 436.15 | K12: =_xlfn.XLOOKUP(A12,MEDIDAS!A:A,MEDIDAS!B:B,"0",0)*5 -> 2.1666667 | L12: =SUM(K12,(_xlfn.XLOOKUP(A12,MEDIDAS!A:A,MEDIDAS!B:B,"0",0)*5)) -> 4.3333333 | M12: =IF(F12>=SUM(L12,_xlfn.XLOOKUP(A12,'ESTOQUE SETEMBRO'!A:A,'ESTOQUE SETEMBRO'!F:F,,0))/2*1.2,"OVER",IF(F12<=SUM(L12,_xlfn.XLOOKUP(A12,'ESTOQUE SETEMBRO'!A:A,'ESTOQUE SETEMBRO'!F:F,,0))/2*1.1,"IDEAL","OUT")) -> OVER | N12: =IF('ESTOQUE SETEMBRO'!$E12>=0,"setembro","sem abastecimento") -> setembro | O12: 45536
A13: SKU0012 | B13: Capa para Celular | C13: =3.09*1*7 -> 21.63 | D13: 17.6 | E13: =IF(Tabela1[[#This Row],[ESTOQUE_INICIAL]]>=150,Tabela1[[#This Row],[ESTOQUE_INICIAL]]*0,IF(Tabela1[[#This Row],[ESTOQUE_INICIAL]]=0,SUM(Tabela1[[#This Row],[ESTOQUE_INICIAL]],150),Tabela1[[#This Row],[ESTOQUE_INICIAL]]*5)) -> 88 | F13: =SUM(E13,D13) -> 105.6 | G13: 5.5 | H13: 5 | I13: Acessórios | J13: =Tabela1[[#This Row],[ESTOQUE_INICIAL]]*Tabela1[[#This Row],[CUSTO_UNITARIO_M-1]]+Tabela1[[#This Row],[ABASTECIMENTO]]*Tabela1[[#This Row],[CUSTO_UNITARIO_M0]] -> 536.8 | K13: =_xlfn.XLOOKUP(A13,MEDIDAS!A:A,MEDIDAS!B:B,"0",0)*5 -> 2.6666667 | L13: =SUM(K13,(_xlfn.XLOOKUP(A13,MEDIDAS!A:A,MEDIDAS!B:B,"0",0)*5)) -> 5.3333333 | M13: =IF(F13>=SUM(L13,_xlfn.XLOOKUP(A13,'ESTOQUE SETEMBRO'!A:A,'ESTOQUE SETEMBRO'!F:F,,0))/2*1.2,"OVER",IF(F13<=SUM(L13,_xlfn.XLOOKUP(A13,'ESTOQUE SETEMBRO'!A:A,'ESTOQUE SETEMBRO'!F:F,,0))/2*1.1,"IDEAL","OUT")) -> OVER | N13: =IF('ESTOQUE SETEMBRO'!$E13>=0,"setembro","sem abastecimento") -> setembro | O13: 45536
... A1101: SKU1100 | B1101: Ventilador de Mesa | C1101: =3.09*1*7 -> 21.63 | D1101: 22 | E1101: =IF(Tabela1[[#This Row],[ESTOQUE_INICIAL]]>=150,Tabela1[[#This Row],[ESTOQUE_INICIAL]]*0,IF(Tabela1[[#This Row],[ESTOQUE_INICIAL]]=0,SUM(Tabela1[[#This Row],[ESTOQUE_INICIAL]],150),Tabela1[[#This Row],[ESTOQUE_INICIAL]]*5)) -> 110 | F1101: =SUM(E1101,D1101) -> 132 | G1101: 22 | H1101: 20 | I1101: Eletrodomésticos | J1101: =Tabela1[[#This Row],[ESTOQUE_INICIAL]]*Tabela1[[#This Row],[CUSTO_UNITARIO_M-1]]+Tabela1[[#This Row],[ABASTECIMENTO]]*Tabela1[[#This Row],[CUSTO_UNITARIO_M0]] -> 2684 | K1101: =_xlfn.XLOOKUP(A1101,MEDIDAS!A:A,MEDIDAS!B:B,"0",0)*5 -> 3.3333333 | L1101: =SUM(K1101,(_xlfn.XLOOKUP(A1101,MEDIDAS!A:A,MEDIDAS!B:B,"0",0)*5)) -> 6.6666667 | M1101: =IF(F1101>=SUM(L1101,_xlfn.XLOOKUP(A1101,'ESTOQUE SETEMBRO'!A:A,'ESTOQUE SETEMBRO'!F:F,,0))/2*1.2,"OVER",IF(F1101<=SUM(L1101,_xlfn.XLOOKUP(A1101,'ESTOQUE SETEMBRO'!A:A,'ESTOQUE SETEMBRO'!F:F,,0))/2*1.1,"IDEAL","OUT")) -> OVER | N1101: =IF('ESTOQUE SETEMBRO'!$E1101>=0,"setembro","sem abastecimento") -> setembro | O1101: 45536

Sheet ESTOQUE OUTUBRO
A1: SKU | B1: SKU_DESCRICAO | C1: ESTOQUE_DE_SEGURANCA | D1: ESTOQUE_INICIAL | E1: ABASTECIMENTO | F1: ESTOQUE_ATUAL | G1: CUSTO_UNITARIO_M-1 | H1: CUSTO_UNITARIO_M0 | I1: CATEGORIA | J1: CUSTO_TOTAL_POR_ITEM | K1: ESTOQUE_MINIMO | L1: PONTO_DE_REPOSICAO | M1: CATEGORIA_DE_ESTOQUE | N1: ULTIMO_ABASTECIMENTO_OUTUBRO | O1: ESTOQUE_MES
A2: SKU0001 | B2: Fone de Ouvido Bluetooth | C2: =3.09*2*7 -> 43.26 | D2: =_xlfn.XLOOKUP(Tabela3[[#This Row],[SKU]],'ESTOQUE SETEMBRO'!A:A,'ESTOQUE SETEMBRO'!F:F,,0)-_xlfn.XLOOKUP(Tabela3[[#This Row],[SKU]],'VENDA MES'!A:A,'VENDA MES'!B:B,0,0) -> 196 | E2: =IF(D2<=0,SUM(Tabela3[[#This Row],[PONTO_DE_REPOSICAO]]*2.5,Tabela3[[#This Row],[ESTOQUE_INICIAL]]),IF(AND(Tabela3[[#This Row],[ESTOQUE_INICIAL]]<=Tabela3[[#This Row],[PONTO_DE_REPOSICAO]],Tabela3[[#This Row],[ESTOQUE_INICIAL]]>0),L2*2.5,D2*0)) -> 0 | F2: =SUM(E2,D2) -> 196 | G2: 24 | H2: 24 | I2: Eletrônicos | J2: =H2*D2 -> 4704 | K2: =_xlfn.XLOOKUP(A2,MEDIDAS!A:A,MEDIDAS!C:C,,0)*5 -> 5 | L2: =SUM(K2,_xlfn.XLOOKUP(A2,MEDIDAS!A:A,MEDIDAS!C:C,,0)*5) -> 10 | M2: =IF(F2>=SUM(L2,_xlfn.XLOOKUP(A2,'ESTOQUE SETEMBRO'!A:A,'ESTOQUE SETEMBRO'!F:F,,0))/2*1.2,"OVER",IF(F2<=SUM(L2,_xlfn.XLOOKUP(A2,'ESTOQUE SETEMBRO'!A:A,'ESTOQUE SETEMBRO'!F:F,,0))/2*1.1,"IDEAL","OUT")) -> OVER | N2: =IF('ESTOQUE OUTUBRO'!$D2>=0,"outubro","setembro") -> outubro | O2: 45566
A3: SKU0002 | B3: Fone de Ouvido Bluetooth | C3: =3.09*2*7 -> 43.26 | D3: =_xlfn.XLOOKUP(Tabela3[[#This Row],[SKU]],'ESTOQUE SETEMBRO'!A:A,'ESTOQUE SETEMBRO'!F:F,,0)-_xlfn.XLOOKUP(Tabela3[[#This Row],[SKU]],'VENDA MES'!A:A,'VENDA MES'!B:B,0,0) -> 112 | E3: =IF(D3<=0,SUM(Tabela3[[#This Row],[PONTO_DE_REPOSICAO]]*2.5,Tabela3[[#This Row],[ESTOQUE_INICIAL]]),IF(AND(Tabela3[[#This Row],[ESTOQUE_INICIAL]]<=Tabela3[[#This Row],[PONTO_DE_REPOSICAO]],Tabela3[[#This Row],[ESTOQUE_INICIAL]]>0),L3*2.5,D3*0)) -> 0 | F3: =SUM(E3,D3) -> 112 | G3: 24 | H3: 24 | I3: Eletrônicos | J3: =H3*D3 -> 2688 | K3: =_xlfn.XLOOKUP(A3,MEDIDAS!A:A,MEDIDAS!C:C,,0)*5 -> 4.75 | L3: =SUM(K3,_xlfn.XLOOKUP(A3,MEDIDAS!A:A,MEDIDAS!C:C,,0)*5) -> 9.5 | M3: =IF(F3>=SUM(L3,_xlfn.XLOOKUP(A3,'ESTOQUE SETEMBRO'!A:A,'ESTOQUE SETEMBRO'!F:F,,0))/2*1.2,"OVER",IF(F3<=SUM(L3,_xlfn.XLOOKUP(A3,'ESTOQUE SETEMBRO'!A:A,'ESTOQUE SETEMBRO'!F:F,,0))/2*1.1,"IDEAL","OUT")) -> OVER | N3: =IF('ESTOQUE OUTUBRO'!$D3>=0,"outubro","setembro") -> outubro | O3: 45566
A4: SKU0003 | B4: Fone de Ouvido Bluetooth | C4: =3.09*2*7 -> 43.26 | D4: =_xlfn.XLOOKUP(Tabela3[[#This Row],[SKU]],'ESTOQUE SETEMBRO'!A:A,'ESTOQUE SETEMBRO'!F:F,,0)-_xlfn.XLOOKUP(Tabela3[[#This Row],[SKU]],'VENDA MES'!A:A,'VENDA MES'!B:B,0,0) -> 235.2 | E4: =IF(D4<=0,SUM(Tabela3[[#This Row],[PONTO_DE_REPOSICAO]]*2.5,Tabela3[[#This Row],[ESTOQUE_INICIAL]]),IF(AND(Tabela3[[#This Row],[ESTOQUE_INICIAL]]<=Tabela3[[#This Row],[PONTO_DE_REPOSICAO]],Tabela3[[#This Row],[ESTOQUE_INICIAL]]>0),L4*2.5,D4*0)) -> 0 | F4: =SUM(E4,D4) -> 235.2 | G4: 24 | H4: 24 | I4: Eletrônicos | J4: =H4*D4 -> 5644.8 | K4: =_xlfn.XLOOKUP(A4,MEDIDAS!A:A,MEDIDAS!C:C,,0)*5 -> 6.6666667 | L4: =SUM(K4,_xlfn.XLOOKUP(A4,MEDIDAS!A:A,MEDIDAS!C:C,,0)*5) -> 13.333333 | M4: =IF(F4>=SUM(L4,_xlfn.XLOOKUP(A4,'ESTOQUE SETEMBRO'!A:A,'ESTOQUE SETEMBRO'!F:F,,0))/2*1.2,"OVER",IF(F4<=SUM(L4,_xlfn.XLOOKUP(A4,'ESTOQUE SETEMBRO'!A:A,'ESTOQUE SETEMBRO'!F:F,,0))/2*1.1,"IDEAL","OUT")) -> OVER | N4: =IF('ESTOQUE OUTUBRO'!$D4>=0,"outubro","setembro") -> outubro | O4: 45566
A5: SKU0004 | B5: Fone de Ouvido Bluetooth | C5: =3.09*2*7 -> 43.26 | D5: =_xlfn.XLOOKUP(Tabela3[[#This Row],[SKU]],'ESTOQUE SETEMBRO'!A:A,'ESTOQUE SETEMBRO'!F:F,,0)-_xlfn.XLOOKUP(Tabela3[[#This Row],[SKU]],'VENDA MES'!A:A,'VENDA MES'!B:B,0,0) -> 61.6 | E5: =IF(D5<=0,SUM(Tabela3[[#This Row],[PONTO_DE_REPOSICAO]]*2.5,Tabela3[[#This Row],[ESTOQUE_INICIAL]]),IF(AND(Tabela3[[#This Row],[ESTOQUE_INICIAL]]<=Tabela3[[#This Row],[PONTO_DE_REPOSICAO]],Tabela3[[#This Row],[ESTOQUE_INICIAL]]>0),L5*2.5,D5*0)) -> 0 | F5: =SUM(E5,D5) -> 61.6 | G5: 24 | H5: 24 | I5: Eletrônicos | J5: =H5*D5 -> 1478.4 | K5: =_xlfn.XLOOKUP(A5,MEDIDAS!A:A,MEDIDAS!C:C,,0)*5 -> 3.3333333 | L5: =SUM(K5,_xlfn.XLOOKUP(A5,MEDIDAS!A:A,MEDIDAS!C:C,,0)*5) -> 6.6666667 | M5: =IF(F5>=SUM(L5,_xlfn.XLOOKUP(A5,'ESTOQUE SETEMBRO'!A:A,'ESTOQUE SETEMBRO'!F:F,,0))/2*1.2,"OVER",IF(F5<=SUM(L5,_xlfn.XLOOKUP(A5,'ESTOQUE SETEMBRO'!A:A,'ESTOQUE SETEMBRO'!F:F,,0))/2*1.1,"IDEAL","OUT")) -> OVER | N5: =IF('ESTOQUE OUTUBRO'!$D5>=0,"outubro","setembro") -> outubro | O5: 45566
A6: SKU0005 | B6: Fone de Ouvido Bluetooth | C6: =3.09*2*7 -> 43.26 | D6: =_xlfn.XLOOKUP(Tabela3[[#This Row],[SKU]],'ESTOQUE SETEMBRO'!A:A,'ESTOQUE SETEMBRO'!F:F,,0)-_xlfn.XLOOKUP(Tabela3[[#This Row],[SKU]],'VENDA MES'!A:A,'VENDA MES'!B:B,0,0) -> 56 | E6: =IF(D6<=0,SUM(Tabela3[[#This Row],[PONTO_DE_REPOSICAO]]*2.5,Tabela3[[#This Row],[ESTOQUE_INICIAL]]),IF(AND(Tabela3[[#This Row],[ESTOQUE_INICIAL]]<=Tabela3[[#This Row],[PONTO_DE_REPOSICAO]],Tabela3[[#This Row],[ESTOQUE_INICIAL]]>0),L6*2.5,D6*0)) -> 0 | F6: =SUM(E6,D6) -> 56 | G6: 24 | H6: 24 | I6: Eletrônicos | J6: =H6*D6 -> 1344 | K6: =_xlfn.XLOOKUP(A6,MEDIDAS!A:A,MEDIDAS!C:C,,0)*5 -> 7.4166667 | L6: =SUM(K6,_xlfn.XLOOKUP(A6,MEDIDAS!A:A,MEDIDAS!C:C,,0)*5) -> 14.833333 | M6: =IF(F6>=SUM(L6,_xlfn.XLOOKUP(A6,'ESTOQUE SETEMBRO'!A:A,'ESTOQUE SETEMBRO'!F:F,,0))/2*1.2,"OVER",IF(F6<=SUM(L6,_xlfn.XLOOKUP(A6,'ESTOQUE SETEMBRO'!A:A,'ESTOQUE SETEMBRO'!F:F,,0))/2*1.1,"IDEAL","OUT")) -> OVER | N6: =IF('ESTOQUE OUTUBRO'!$D6>=0,"outubro","setembro") -> outubro | O6: 45566
A7: SKU0006 | B7: Fone de Ouvido Bluetooth | C7: =3.09*2*7 -> 43.26 | D7: =_xlfn.XLOOKUP(Tabela3[[#This Row],[SKU]],'ESTOQUE SETEMBRO'!A:A,'ESTOQUE SETEMBRO'!F:F,,0)-_xlfn.XLOOKUP(Tabela3[[#This Row],[SKU]],'VENDA MES'!A:A,'VENDA MES'!B:B,0,0) -> 150 | E7: =IF(D7<=0,SUM(Tabela3[[#This Row],[PONTO_DE_REPOSICAO]]*2.5,Tabela3[[#This Row],[ESTOQUE_INICIAL]]),IF(AND(Tabela3[[#This Row],[ESTOQUE_INICIAL]]<=Tabela3[[#This Row],[PONTO_DE_REPOSICAO]],Tabela3[[#This Row],[ESTOQUE_INICIAL]]>0),L7*2.5,D7*0)) -> 0 | F7: =SUM(E7,D7) -> 150 | G7: 24 | H7: 24 | I7: Eletrônicos | J7: =H7*D7 -> 3600 | K7: =_xlfn.XLOOKUP(A7,MEDIDAS!A:A,MEDIDAS!C:C,,0)*5 -> 2 | L7: =SUM(K7,_xlfn.XLOOKUP(A7,MEDIDAS!A:A,MEDIDAS!C:C,,0)*5) -> 4 | M7: =IF(F7>=SUM(L7,_xlfn.XLOOKUP(A7,'ESTOQUE SETEMBRO'!A:A,'ESTOQUE SETEMBRO'!F:F,,0))/2*1.2,"OVER",IF(F7<=SUM(L7,_xlfn.XLOOKUP(A7,'ESTOQUE SETEMBRO'!A:A,'ESTOQUE SETEMBRO'!F:F,,0))/2*1.1,"IDEAL","OUT")) -> OVER | N7: =IF('ESTOQUE OUTUBRO'!$D7>=0,"outubro","setembro") -> outubro | O7: 45566
A8: SKU0007 | B8: Fone de Ouvido Bluetooth | C8: =3.09*2*7 -> 43.26 | D8: =_xlfn.XLOOKUP(Tabela3[[#This Row],[SKU]],'ESTOQUE SETEMBRO'!A:A,'ESTOQUE SETEMBRO'!F:F,,0)-_xlfn.XLOOKUP(Tabela3[[#This Row],[SKU]],'VENDA MES'!A:A,'VENDA MES'!B:B,0,0) -> 162.4 | E8: =IF(D8<=0,SUM(Tabela3[[#This Row],[PONTO_DE_REPOSICAO]]*2.5,Tabela3[[#This Row],[ESTOQUE_INICIAL]]),IF(AND(Tabela3[[#This Row],[ESTOQUE_INICIAL]]<=Tabela3[[#This Row],[PONTO_DE_REPOSICAO]],Tabela3[[#This Row],[ESTOQUE_INICIAL]]>0),L8*2.5,D8*0)) -> 0 | F8: =SUM(E8,D8) -> 162.4 | G8: 24 | H8: 24 | I8: Eletrônicos | J8: =H8*D8 -> 3897.6 | K8: =_xlfn.XLOOKUP(A8,MEDIDAS!A:A,MEDIDAS!C:C,,0)*5 -> 4.25 | L8: =SUM(K8,_xlfn.XLOOKUP(A8,MEDIDAS!A:A,MEDIDAS!C:C,,0)*5) -> 8.5 | M8: =IF(F8>=SUM(L8,_xlfn.XLOOKUP(A8,'ESTOQUE SETEMBRO'!A:A,'ESTOQUE SETEMBRO'!F:F,,0))/2*1.2,"OVER",IF(F8<=SUM(L8,_xlfn.XLOOKUP(A8,'ESTOQUE SETEMBRO'!A:A,'ESTOQUE SETEMBRO'!F:F,,0))/2*1.1,"IDEAL","OUT")) -> OVER | N8: =IF('ESTOQUE OUTUBRO'!$D8>=0,"outubro","setembro") -> outubro | O8: 45566
A9: SKU0008 | B9: Fone de Ouvido Bluetooth | C9: =3.09*2*7 -> 43.26 | D9: =_xlfn.XLOOKUP(Tabela3[[#This Row],[SKU]],'ESTOQUE SETEMBRO'!A:A,'ESTOQUE SETEMBRO'!F:F,,0)-_xlfn.XLOOKUP(Tabela3[[#This Row],[SKU]],'VENDA MES'!A:A,'VENDA MES'!B:B,0,0) -> 168 | E9: =IF(D9<=0,SUM(Tabela3[[#This Row],[PONTO_DE_REPOSICAO]]*2.5,Tabela3[[#This Row],[ESTOQUE_INICIAL]]),IF(AND(Tabela3[[#This Row],[ESTOQUE_INICIAL]]<=Tabela3[[#This Row],[PONTO_DE_REPOSICAO]],Tabela3[[#This Row],[ESTOQUE_INICIAL]]>0),L9*2.5,D9*0)) -> 0 | F9: =SUM(E9,D9) -> 168 | G9: 24 | H9: 24 | I9: Eletrônicos | J9: =H9*D9 -> 4032 | K9: =_xlfn.XLOOKUP(A9,MEDIDAS!A:A,MEDIDAS!C:C,,0)*5 -> 4.75 | L9: =SUM(K9,_xlfn.XLOOKUP(A9,MEDIDAS!A:A,MEDIDAS!C:C,,0)*5) -> 9.5 | M9: =IF(F9>=SUM(L9,_xlfn.XLOOKUP(A9,'ESTOQUE SETEMBRO'!A:A,'ESTOQUE SETEMBRO'!F:F,,0))/2*1.2,"OVER",IF(F9<=SUM(L9,_xlfn.XLOOKUP(A9,'ESTOQUE SETEMBRO'!A:A,'ESTOQUE SETEMBRO'!F:F,,0))/2*1.1,"IDEAL","OUT")) -> OVER | N9: =IF('ESTOQUE OUTUBRO'!$D9>=0,"outubro","setembro") -> outubro | O9: 45566
A10: SKU0009 | B10: Fone de Ouvido Bluetooth | C10: =3.09*2*7 -> 43.26 | D10: =_xlfn.XLOOKUP(Tabela3[[#This Row],[SKU]],'ESTOQUE SETEMBRO'!A:A,'ESTOQUE SETEMBRO'!F:F,,0)-_xlfn.XLOOKUP(Tabela3[[#This Row],[SKU]],'VENDA MES'!A:A,'VENDA MES'!B:B,0,0) -> 151.2 | E10: =IF(D10<=0,SUM(Tabela3[[#This Row],[PONTO_DE_REPOSICAO]]*2.5,Tabela3[[#This Row],[ESTOQUE_INICIAL]]),IF(AND(Tabela3[[#This Row],[ESTOQUE_INICIAL]]<=Tabela3[[#This Row],[PONTO_DE_REPOSICAO]],Tabela3[[#This Row],[ESTOQUE_INICIAL]]>0),L10*2.5,D10*0)) -> 0 | F10: =SUM(E10,D10) -> 151.2 | G10: 24 | H10: 24 | I10: Eletrônicos | J10: =H10*D10 -> 3628.8 | K10: =_xlfn.XLOOKUP(A10,MEDIDAS!A:A,MEDIDAS!C:C,,0)*5 -> 5.6666667 | L10: =SUM(K10,_xlfn.XLOOKUP(A10,MEDIDAS!A:A,MEDIDAS!C:C,,0)*5) -> 11.333333 | M10: =IF(F10>=SUM(L10,_xlfn.XLOOKUP(A10,'ESTOQUE SETEMBRO'!A:A,'ESTOQUE SETEMBRO'!F:F,,0))/2*1.2,"OVER",IF(F10<=SUM(L10,_xlfn.XLOOKUP(A10,'ESTOQUE SETEMBRO'!A:A,'ESTOQUE SETEMBRO'!F:F,,0))/2*1.1,"IDEAL","OUT")) -> OVER | N10: =IF('ESTOQUE OUTUBRO'!$D10>=0,"outubro","setembro") -> outubro | O10: 45566
A11: SKU0010 | B11: Fone de Ouvido Bluetooth | C11: =3.09*2*7 -> 43.26 | D11: =_xlfn.XLOOKUP(Tabela3[[#This Row],[SKU]],'ESTOQUE SETEMBRO'!A:A,'ESTOQUE SETEMBRO'!F:F,,0)-_xlfn.XLOOKUP(Tabela3[[#This Row],[SKU]],'VENDA MES'!A:A,'VENDA MES'!B:B,0,0) -> 134.4 | E11: =IF(D11<=0,SUM(Tabela3[[#This Row],[PONTO_DE_REPOSICAO]]*2.5,Tabela3[[#This Row],[ESTOQUE_INICIAL]]),IF(AND(Tabela3[[#This Row],[ESTOQUE_INICIAL]]<=Tabela3[[#This Row],[PONTO_DE_REPOSICAO]],Tabela3[[#This Row],[ESTOQUE_INICIAL]]>0),L11*2.5,D11*0)) -> 0 | F11: =SUM(E11,D11) -> 134.4 | G11: 24 | H11: 24 | I11: Eletrônicos | J11: =H11*D11 -> 3225.6 | K11: =_xlfn.XLOOKUP(A11,MEDIDAS!A:A,MEDIDAS!C:C,,0)*5 -> 7.5 | L11: =SUM(K11,_xlfn.XLOOKUP(A11,MEDIDAS!A:A,MEDIDAS!C:C,,0)*5) -> 15 | M11: =IF(F11>=SUM(L11,_xlfn.XLOOKUP(A11,'ESTOQUE SETEMBRO'!A:A,'ESTOQUE SETEMBRO'!F:F,,0))/2*1.2,"OVER",IF(F11<=SUM(L11,_xlfn.XLOOKUP(A11,'ESTOQUE SETEMBRO'!A:A,'ESTOQUE SETEMBRO'!F:F,,0))/2*1.1,"IDEAL","OUT")) -> OVER | N11: =IF('ESTOQUE OUTUBRO'!$D11>=0,"outubro","setembro") -> outubro | O11: 45566
A12: SKU0011 | B12: Capa para Celular | C12: =3.09*2*7 -> 43.26 | D12: =_xlfn.XLOOKUP(Tabela3[[#This Row],[SKU]],'ESTOQUE SETEMBRO'!A:A,'ESTOQUE SETEMBRO'!F:F,,0)-_xlfn.XLOOKUP(Tabela3[[#This Row],[SKU]],'VENDA MES'!A:A,'VENDA MES'!B:B,0,0) -> 72.8 | E12: =IF(D12<=0,SUM(Tabela3[[#This Row],[PONTO_DE_REPOSICAO]]*2.5,Tabela3[[#This Row],[ESTOQUE_INICIAL]]),IF(AND(Tabela3[[#This Row],[ESTOQUE_INICIAL]]<=Tabela3[[#This Row],[PONTO_DE_REPOSICAO]],Tabela3[[#This Row],[ESTOQUE_INICIAL]]>0),L12*2.5,D12*0)) -> 0 | F12: =SUM(E12,D12) -> 72.8 | G12: 5 | H12: 5 | I12: Acessórios | J12: =H12*D12 -> 364 | K12: =_xlfn.XLOOKUP(A12,MEDIDAS!A:A,MEDIDAS!C:C,,0)*5 -> 3.5 | L12: =SUM(K12,_xlfn.XLOOKUP(A12,MEDIDAS!A:A,MEDIDAS!C:C,,0)*5) -> 7 | M12: =IF(F12>=SUM(L12,_xlfn.XLOOKUP(A12,'ESTOQUE SETEMBRO'!A:A,'ESTOQUE SETEMBRO'!F:F,,0))/2*1.2,"OVER",IF(F12<=SUM(L12,_xlfn.XLOOKUP(A12,'ESTOQUE SETEMBRO'!A:A,'ESTOQUE SETEMBRO'!F:F,,0))/2*1.1,"IDEAL","OUT")) -> OVER | N12: =IF('ESTOQUE OUTUBRO'!$D12>=0,"outubro","setembro") -> outubro | O12: 45566
A13: SKU0012 | B13: Capa para Celular | C13: =3.09*2*7 -> 43.26 | D13: =_xlfn.XLOOKUP(Tabela3[[#This Row],[SKU]],'ESTOQUE SETEMBRO'!A:A,'ESTOQUE SETEMBRO'!F:F,,0)-_xlfn.XLOOKUP(Tabela3[[#This Row],[SKU]],'VENDA MES'!A:A,'VENDA MES'!B:B,0,0) -> 89.6 | E13: =IF(D13<=0,SUM(Tabela3[[#This Row],[PONTO_DE_REPOSICAO]]*2.5,Tabela3[[#This Row],[ESTOQUE_INICIAL]]),IF(AND(Tabela3[[#This Row],[ESTOQUE_INICIAL]]<=Tabela3[[#This Row],[PONTO_DE_REPOSICAO]],Tabela3[[#This Row],[ESTOQUE_INICIAL]]>0),L13*2.5,D13*0)) -> 0 | F13: =SUM(E13,D13) -> 89.6 | G13: 5 | H13: 5 | I13: Acessórios | J13: =H13*D13 -> 448 | K13: =_xlfn.XLOOKUP(A13,MEDIDAS!A:A,MEDIDAS!C:C,,0)*5 -> 3.0833333 | L13: =SUM(K13,_xlfn.XLOOKUP(A13,MEDIDAS!A:A,MEDIDAS!C:C,,0)*5) -> 6.1666667 | M13: =IF(F13>=SUM(L13,_xlfn.XLOOKUP(A13,'ESTOQUE SETEMBRO'!A:A,'ESTOQUE SETEMBRO'!F:F,,0))/2*1.2,"OVER",IF(F13<=SUM(L13,_xlfn.XLOOKUP(A13,'ESTOQUE SETEMBRO'!A:A,'ESTOQUE SETEMBRO'!F:F,,0))/2*1.1,"IDEAL","OUT")) -> OVER | N13: =IF('ESTOQUE OUTUBRO'!$D13>=0,"outubro","setembro") -> outubro | O13: 45566
... A1101: SKU1100 | B1101: Ventilador de Mesa | C1101: =3.09*2*7 -> 43.26 | D1101: =_xlfn.XLOOKUP(Tabela3[[#This Row],[SKU]],'ESTOQUE SETEMBRO'!A:A,'ESTOQUE SETEMBRO'!F:F,,0)-_xlfn.XLOOKUP(Tabela3[[#This Row],[SKU]],'VENDA MES'!A:A,'VENDA MES'!B:B,0,0) -> 112 | E1101: =IF(D1101<=0,SUM(Tabela3[[#This Row],[PONTO_DE_REPOSICAO]]*2.5,Tabela3[[#This Row],[ESTOQUE_INICIAL]]),IF(AND(Tabela3[[#This Row],[ESTOQUE_INICIAL]]<=Tabela3[[#This Row],[PONTO_DE_REPOSICAO]],Tabela3[[#This Row],[ESTOQUE_INICIAL]]>0),L1101*2.5,D1101*0)) -> 0 | F1101: =SUM(E1101,D1101) -> 112 | G1101: 20 | H1101: 20 | I1101: Eletrodomésticos | J1101: =H1101*D1101 -> 2240 | K1101: =_xlfn.XLOOKUP(A1101,MEDIDAS!A:A,MEDIDAS!C:C,,0)*5 -> 1.6666667 | L1101: =SUM(K1101,_xlfn.XLOOKUP(A1101,MEDIDAS!A:A,MEDIDAS!C:C,,0)*5) -> 3.3333333 | M1101: =IF(F1101>=SUM(L1101,_xlfn.XLOOKUP(A1101,'ESTOQUE SETEMBRO'!A:A,'ESTOQUE SETEMBRO'!F:F,,0))/2*1.2,"OVER",IF(F1101<=SUM(L1101,_xlfn.XLOOKUP(A1101,'ESTOQUE SETEMBRO'!A:A,'ESTOQUE SETEMBRO'!F:F,,0))/2*1.1,"IDEAL","OUT")) -> OVER | N1101: =IF('ESTOQUE OUTUBRO'!$D1101>=0,"outubro","setembro") -> outubro | O1101: 45566

Sheet ESTOQUE NOVEMBRO
A1: SKU | B1: SKU_DESCRICAO | C1: ESTOQUE_DE_SEGURANCA | D1: ESTOQUE_INICIAL | E1: ABASTECIMENTO | F1: ESTOQUE_ATUAL | G1: CUSTO_UNITARIO_M-1 | H1: CUSTO_UNITARIO_M0 | I1: CATEGORIA | J1: CUSTO_TOTAL_POR_ITEM | K1: ESTOQUE_MINIMO | L1: PONTO_DE_REPOSICAO | M1: CATEGORIA_DE_ESTOQUE | N1: ULTIMO_ABASTECIMENTO_NOVEMBRO | O1: ESTOQUE_MES
A2: SKU0001 | B2: Fone de Ouvido Bluetooth | C2: =3.09*3*7 -> 64.89 | D2: =_xlfn.XLOOKUP(Tabela4[[#This Row],[SKU]],'ESTOQUE OUTUBRO'!A:A,'ESTOQUE OUTUBRO'!F:F,,0)-_xlfn.XLOOKUP(Tabela4[[#This Row],[SKU]],'VENDA MES'!E:E,'VENDA MES'!F:F,0,0) -> 171 | E2: =IF(D2<=0,(L2 * 2.5) - D2,IF(AND(Tabela4[[#This Row],[ESTOQUE_INICIAL]]<=Tabela4[[#This Row],[PONTO_DE_REPOSICAO]],Tabela4[[#This Row],[ESTOQUE_INICIAL]]>0),L2*1.5,D2*0)) -> 0 | F2: =SUM(E2,D2) -> 171 | G2: 24 | H2: 48 | I2: Eletrônicos | J2: ='ESTOQUE NOVEMBRO'!$D2*'ESTOQUE NOVEMBRO'!$G2+'ESTOQUE NOVEMBRO'!$E2*'ESTOQUE NOVEMBRO'!$H2 -> 4104 | K2: =_xlfn.XLOOKUP(A2,MEDIDAS!A:A,MEDIDAS!D:D,,0)*5 -> 5.7222222 | L2: =SUM(K2,_xlfn.XLOOKUP(A2,MEDIDAS!A:A,MEDIDAS!D:D,,0)*5) -> 11.444444 | M2: =IF(Tabela4[[#This Row],[ESTOQUE_ATUAL]]>=SUM(AVERAGE(_xlfn.XLOOKUP(Tabela4[[#This Row],[SKU]],'VENDA MES'!A:A,'VENDA MES'!B:B,0,0),_xlfn.XLOOKUP(Tabela4[[#This Row],[SKU]],'VENDA MES'!E:E,'VENDA MES'!F:F,0,0)),STDEV(_xlfn.XLOOKUP(Tabela4[[#This Row],[SKU]],'VENDA MES'!A:A,'VENDA MES'!B:B,0,0),_xlfn.XLOOKUP(Tabela4[[#This Row],[SKU]],'VENDA MES'!E:E,'VENDA MES'!F:F,0,0))),"OVER",IF(Tabela4[[#This Row],[SKU]]<=AVERAGE(_xlfn.XLOOKUP(Tabela4[[#This Row],[SKU]],'VENDA MES'!A:A,'VENDA MES'!B:B,0,0),_xlfn.XLOOKUP(Tabela4[[#This Row],[SKU]],'VENDA MES'!E:E,'VENDA MES'!F:F,0,0))-STDEV(_xlfn.XLOOKUP(Tabela4[[#This Row],[SKU]],'VENDA MES'!A:A,'VENDA MES'!B:B,0,0),_xlfn.XLOOKUP(Tabela4[[#This Row],[SKU]],'VENDA MES'!E:E,'VENDA MES'!F:F,0,0)),"OUT","IDEAL")) -> OVER | N2: =IF('ESTOQUE NOVEMBRO'!$E2>0,"Novembro","outubro") -> outubro | O2: 45597
A3: SKU0002 | B3: Fone de Ouvido Bluetooth | C3: =3.09*3*7 -> 64.89 | D3: =_xlfn.XLOOKUP(Tabela4[[#This Row],[SKU]],'ESTOQUE OUTUBRO'!A:A,'ESTOQUE OUTUBRO'!F:F,,0)-_xlfn.XLOOKUP(Tabela4[[#This Row],[SKU]],'VENDA MES'!E:E,'VENDA MES'!F:F,0,0) -> 75 | E3: =IF(D3<=0,(L3 * 2.5) - D3,IF(AND(Tabela4[[#This Row],[ESTOQUE_INICIAL]]<=Tabela4[[#This Row],[PONTO_DE_REPOSICAO]],Tabela4[[#This Row],[ESTOQUE_INICIAL]]>0),L3*1.5,D3*0)) -> 0 | F3: =SUM(E3,D3) -> 75 | G3: 24 | H3: 48 | I3: Eletrônicos | J3: ='ESTOQUE NOVEMBRO'!$D3*'ESTOQUE NOVEMBRO'!$G3+'ESTOQUE NOVEMBRO'!$E3*'ESTOQUE NOVEMBRO'!$H3 -> 1800 | K3: =_xlfn.XLOOKUP(A3,MEDIDAS!A:A,MEDIDAS!D:D,,0)*5 -> 5.6111111 | L3: =SUM(K3,_xlfn.XLOOKUP(A3,MEDIDAS!A:A,MEDIDAS!D:D,,0)*5) -> 11.222222 | M3: =IF(Tabela4[[#This Row],[ESTOQUE_ATUAL]]>=SUM(AVERAGE(_xlfn.XLOOKUP(Tabela4[[#This Row],[SKU]],'VENDA MES'!A:A,'VENDA MES'!B:B,0,0),_xlfn.XLOOKUP(Tabela4[[#This Row],[SKU]],'VENDA MES'!E:E,'VENDA MES'!F:F,0,0)),STDEV(_xlfn.XLOOKUP(Tabela4[[#This Row],[SKU]],'VENDA MES'!A:A,'VENDA MES'!B:B,0,0),_xlfn.XLOOKUP(Tabela4[[#This Row],[SKU]],'VENDA MES'!E:E,'VENDA MES'!F:F,0,0))),"OVER",IF(Tabela4[[#This Row],[SKU]]<=AVERAGE(_xlfn.XLOOKUP(Tabela4[[#This Row],[SKU]],'VENDA MES'!A:A,'VENDA MES'!B:B,0,0),_xlfn.XLOOKUP(Tabela4[[#This Row],[SKU]],'VENDA MES'!E:E,'VENDA MES'!F:F,0,0))-STDEV(_xlfn.XLOOKUP(Tabela4[[#This Row],[SKU]],'VENDA MES'!A:A,'VENDA MES'!B:B,0,0),_xlfn.XLOOKUP(Tabela4[[#This Row],[SKU]],'VENDA MES'!E:E,'VENDA MES'!F:F,0,0)),"OUT","IDEAL")) -> OVER | N3: =IF('ESTOQUE NOVEMBRO'!$E3>0,"Novembro","outubro") -> outubro | O3: 45597
A4: SKU0003 | B4: Fone de Ouvido Bluetooth | C4: =3.09*3*7 -> 64.89 | D4: =_xlfn.XLOOKUP(Tabela4[[#This Row],[SKU]],'ESTOQUE OUTUBRO'!A:A,'ESTOQUE OUTUBRO'!F:F,,0)-_xlfn.XLOOKUP(Tabela4[[#This Row],[SKU]],'VENDA MES'!E:E,'VENDA MES'!F:F,0,0) -> 197.2 | E4: =IF(D4<=0,(L4 * 2.5) - D4,IF(AND(Tabela4[[#This Row],[ESTOQUE_INICIAL]]<=Tabela4[[#This Row],[PONTO_DE_REPOSICAO]],Tabela4[[#This Row],[ESTOQUE_INICIAL]]>0),L4*1.5,D4*0)) -> 0 | F4: =SUM(E4,D4) -> 197.2 | G4: 24 | H4: 48 | I4: Eletrônicos | J4: ='ESTOQUE NOVEMBRO'!$D4*'ESTOQUE NOVEMBRO'!$G4+'ESTOQUE NOVEMBRO'!$E4*'ESTOQUE NOVEMBRO'!$H4 -> 4732.8 | K4: =_xlfn.XLOOKUP(A4,MEDIDAS!A:A,MEDIDAS!D:D,,0)*5 -> 6.7222222 | L4: =SUM(K4,_xlfn.XLOOKUP(A4,MEDIDAS!A:A,MEDIDAS!D:D,,0)*5) -> 13.444444 | M4: =IF(Tabela4[[#This Row],[ESTOQUE_ATUAL]]>=SUM(AVERAGE(_xlfn.XLOOKUP(Tabela4[[#This Row],[SKU]],'VENDA MES'!A:A,'VENDA MES'!B:B,0,0),_xlfn.XLOOKUP(Tabela4[[#This Row],[SKU]],'VENDA MES'!E:E,'VENDA MES'!F:F,0,0)),STDEV(_xlfn.XLOOKUP(Tabela4[[#This Row],[SKU]],'VENDA MES'!A:A,'VENDA MES'!B:B,0,0),_xlfn.XLOOKUP(Tabela4[[#This Row],[SKU]],'VENDA MES'!E:E,'VENDA MES'!F:F,0,0))),"OVER",IF(Tabela4[[#This Row],[SKU]]<=AVERAGE(_xlfn.XLOOKUP(Tabela4[[#This Row],[SKU]],'VENDA MES'!A:A,'VENDA MES'!B:B,0,0),_xlfn.XLOOKUP(Tabela4[[#This Row],[SKU]],'VENDA MES'!E:E,'VENDA MES'!F:F,0,0))-STDEV(_xlfn.XLOOKUP(Tabela4[[#This Row],[SKU]],'VENDA MES'!A:A,'VENDA MES'!B:B,0,0),_xlfn.XLOOKUP(Tabela4[[#This Row],[SKU]],'VENDA MES'!E:E,'VENDA MES'!F:F,0,0)),"OUT","IDEAL")) -> OVER | N4: =IF('ESTOQUE NOVEMBRO'!$E4>0,"Novembro","outubro") -> outubro | O4: 45597
A5: SKU0004 | B5: Fone de Ouvido Bluetooth | C5: =3.09*3*7 -> 64.89 | D5: =_xlfn.XLOOKUP(Tabela4[[#This Row],[SKU]],'ESTOQUE OUTUBRO'!A:A,'ESTOQUE OUTUBRO'!F:F,,0)-_xlfn.XLOOKUP(Tabela4[[#This Row],[SKU]],'VENDA MES'!E:E,'VENDA MES'!F:F,0,0) -> 32.6 | E5: =IF(D5<=0,(L5 * 2.5) - D5,IF(AND(Tabela4[[#This Row],[ESTOQUE_INICIAL]]<=Tabela4[[#This Row],[PONTO_DE_REPOSICAO]],Tabela4[[#This Row],[ESTOQUE_INICIAL]]>0),L5*1.5,D5*0)) -> 0 | F5: =SUM(E5,D5) -> 32.6 | G5: 24 | H5: 48 | I5: Eletrônicos | J5: ='ESTOQUE NOVEMBRO'!$D5*'ESTOQUE NOVEMBRO'!$G5+'ESTOQUE NOVEMBRO'!$E5*'ESTOQUE NOVEMBRO'!$H5 -> 782.4 | K5: =_xlfn.XLOOKUP(A5,MEDIDAS!A:A,MEDIDAS!D:D,,0)*5 -> 3.9444444 | L5: =SUM(K5,_xlfn.XLOOKUP(A5,MEDIDAS!A:A,MEDIDAS!D:D,,0)*5) -> 7.8888889 | M5: =IF(Tabela4[[#This Row],[ESTOQUE_ATUAL]]>=SUM(AVERAGE(_xlfn.XLOOKUP(Tabela4[[#This Row],[SKU]],'VENDA MES'!A:A,'VENDA MES'!B:B,0,0),_xlfn.XLOOKUP(Tabela4[[#This Row],[SKU]],'VENDA MES'!E:E,'VENDA MES'!F:F,0,0)),STDEV(_xlfn.XLOOKUP(Tabela4[[#This Row],[SKU]],'VENDA MES'!A:A,'VENDA MES'!B:B,0,0),_xlfn.XLOOKUP(Tabela4[[#This Row],[SKU]],'VENDA MES'!E:E,'VENDA MES'!F:F,0,0))),"OVER",IF(Tabela4[[#This Row],[SKU]]<=AVERAGE(_xlfn.XLOOKUP(Tabela4[[#This Row],[SKU]],'VENDA MES'!A:A,'VENDA MES'!B:B,0,0),_xlfn.XLOOKUP(Tabela4[[#This Row],[SKU]],'VENDA MES'!E:E,'VENDA MES'!F:F,0,0))-STDEV(_xlfn.XLOOKUP(Tabela4[[#This Row],[SKU]],'VENDA MES'!A:A,'VENDA MES'!B:B,0,0),_xlfn.XLOOKUP(Tabela4[[#This Row],[SKU]],'VENDA MES'!E:E,'VENDA MES'!F:F,0,0)),"OUT","IDEAL")) -> IDEAL | N5: =IF('ESTOQUE NOVEMBRO'!$E5>0,"Novembro","outubro") -> outubro | O5: 45597
A6: SKU0005 | B6: Fone de Ouvido Bluetooth | C6: =3.09*3*7 -> 64.89 | D6: =_xlfn.XLOOKUP(Tabela4[[#This Row],[SKU]],'ESTOQUE OUTUBRO'!A:A,'ESTOQUE OUTUBRO'!F:F,,0)-_xlfn.XLOOKUP(Tabela4[[#This Row],[SKU]],'VENDA MES'!E:E,'VENDA MES'!F:F,0,0) -> -23 | E6: =IF(D6<=0,(L6 * 2.5) - D6,IF(AND(Tabela4[[#This Row],[ESTOQUE_INICIAL]]<=Tabela4[[#This Row],[PONTO_DE_REPOSICAO]],Tabela4[[#This Row],[ESTOQUE_INICIAL]]>0),L6*1.5,D6*0)) -> 57.444444 | F6: =SUM(E6,D6) -> 34.444444 | G6: 24 | H6: 48 | I6: Eletrônicos | J6: ='ESTOQUE NOVEMBRO'!$D6*'ESTOQUE NOVEMBRO'!$G6+'ESTOQUE NOVEMBRO'!$E6*'ESTOQUE NOVEMBRO'!$H6 -> 2205.3333 | K6: =_xlfn.XLOOKUP(A6,MEDIDAS!A:A,MEDIDAS!D:D,,0)*5 -> 6.8888889 | L6: =SUM(K6,_xlfn.XLOOKUP(A6,MEDIDAS!A:A,MEDIDAS!D:D,,0)*5) -> 13.777778 | M6: =IF(Tabela4[[#This Row],[ESTOQUE_ATUAL]]>=SUM(AVERAGE(_xlfn.XLOOKUP(Tabela4[[#This Row],[SKU]],'VENDA MES'!A:A,'VENDA MES'!B:B,0,0),_xlfn.XLOOKUP(Tabela4[[#This Row],[SKU]],'VENDA MES'!E:E,'VENDA MES'!F:F,0,0)),STDEV(_xlfn.XLOOKUP(Tabela4[[#This Row],[SKU]],'VENDA MES'!A:A,'VENDA MES'!B:B,0,0),_xlfn.XLOOKUP(Tabela4[[#This Row],[SKU]],'VENDA MES'!E:E,'VENDA MES'!F:F,0,0))),"OVER",IF(Tabela4[[#This Row],[SKU]]<=AVERAGE(_xlfn.XLOOKUP(Tabela4[[#This Row],[SKU]],'VENDA MES'!A:A,'VENDA MES'!B:B,0,0),_xlfn.XLOOKUP(Tabela4[[#This Row],[SKU]],'VENDA MES'!E:E,'VENDA MES'!F:F,0,0))-STDEV(_xlfn.XLOOKUP(Tabela4[[#This Row],[SKU]],'VENDA MES'!A:A,'VENDA MES'!B:B,0,0),_xlfn.XLOOKUP(Tabela4[[#This Row],[SKU]],'VENDA MES'!E:E,'VENDA MES'!F:F,0,0)),"OUT","IDEAL")) -> IDEAL | N6: =IF('ESTOQUE NOVEMBRO'!$E6>0,"Novembro","outubro") -> Novembro | O6: 45597
A7: SKU0006 | B7: Fone de Ouvido Bluetooth | C7: =3.09*3*7 -> 64.89 | D7: =_xlfn.XLOOKUP(Tabela4[[#This Row],[SKU]],'ESTOQUE OUTUBRO'!A:A,'ESTOQUE OUTUBRO'!F:F,,0)-_xlfn.XLOOKUP(Tabela4[[#This Row],[SKU]],'VENDA MES'!E:E,'VENDA MES'!F:F,0,0) -> 126 | E7: =IF(D7<=0,(L7 * 2.5) - D7,IF(AND(Tabela4[[#This Row],[ESTOQUE_INICIAL]]<=Tabela4[[#This Row],[PONTO_DE_REPOSICAO]],Tabela4[[#This Row],[ESTOQUE_INICIAL]]>0),L7*1.5,D7*0)) -> 0 | F7: =SUM(E7,D7) -> 126 | G7: 24 | H7: 48 | I7: Eletrônicos | J7: ='ESTOQUE NOVEMBRO'!$D7*'ESTOQUE NOVEMBRO'!$G7+'ESTOQUE NOVEMBRO'!$E7*'ESTOQUE NOVEMBRO'!$H7 -> 3024 | K7: =_xlfn.XLOOKUP(A7,MEDIDAS!A:A,MEDIDAS!D:D,,0)*5 -> 4.7777778 | L7: =SUM(K7,_xlfn.XLOOKUP(A7,MEDIDAS!A:A,MEDIDAS!D:D,,0)*5) -> 9.5555556 | M7: =IF(Tabela4[[#This Row],[ESTOQUE_ATUAL]]>=SUM(AVERAGE(_xlfn.XLOOKUP(Tabela4[[#This Row],[SKU]],'VENDA MES'!A:A,'VENDA MES'!B:B,0,0),_xlfn.XLOOKUP(Tabela4[[#This Row],[SKU]],'VENDA MES'!E:E,'VENDA MES'!F:F,0,0)),STDEV(_xlfn.XLOOKUP(Tabela4[[#This Row],[SKU]],'VENDA MES'!A:A,'VENDA MES'!B:B,0,0),_xlfn.XLOOKUP(Tabela4[[#This Row],[SKU]],'VENDA MES'!E:E,'VENDA MES'!F:F,0,0))),"OVER",IF(Tabela4[[#This Row],[SKU]]<=AVERAGE(_xlfn.XLOOKUP(Tabela4[[#This Row],[SKU]],'VENDA MES'!A:A,'VENDA MES'!B:B,0,0),_xlfn.XLOOKUP(Tabela4[[#This Row],[SKU]],'VENDA MES'!E:E,'VENDA MES'!F:F,0,0))-STDEV(_xlfn.XLOOKUP(Tabela4[[#This Row],[SKU]],'VENDA MES'!A:A,'VENDA MES'!B:B,0,0),_xlfn.XLOOKUP(Tabela4[[#This Row],[SKU]],'VENDA MES'!E:E,'VENDA MES'!F:F,0,0)),"OUT","IDEAL")) -> OVER | N7: =IF('ESTOQUE NOVEMBRO'!$E7>0,"Novembro","outubro") -> outubro | O7: 45597
A8: SKU0007 | B8: Fone de Ouvido Bluetooth | C8: =3.09*3*7 -> 64.89 | D8: =_xlfn.XLOOKUP(Tabela4[[#This Row],[SKU]],'ESTOQUE OUTUBRO'!A:A,'ESTOQUE OUTUBRO'!F:F,,0)-_xlfn.XLOOKUP(Tabela4[[#This Row],[SKU]],'VENDA MES'!E:E,'VENDA MES'!F:F,0,0) -> 140.4 | E8: =IF(D8<=0,(L8 * 2.5) - D8,IF(AND(Tabela4[[#This Row],[ESTOQUE_INICIAL]]<=Tabela4[[#This Row],[PONTO_DE_REPOSICAO]],Tabela4[[#This Row],[ESTOQUE_INICIAL]]>0),L8*1.5,D8*0)) -> 0 | F8: =SUM(E8,D8) -> 140.4 | G8: 24 | H8: 48 | I8: Eletrônicos | J8: ='ESTOQUE NOVEMBRO'!$D8*'ESTOQUE NOVEMBRO'!$G8+'ESTOQUE NOVEMBRO'!$E8*'ESTOQUE NOVEMBRO'!$H8 -> 3369.6 | K8: =_xlfn.XLOOKUP(A8,MEDIDAS!A:A,MEDIDAS!D:D,,0)*5 -> 4.4444444 | L8: =SUM(K8,_xlfn.XLOOKUP(A8,MEDIDAS!A:A,MEDIDAS!D:D,,0)*5) -> 8.8888889 | M8: =IF(Tabela4[[#This Row],[ESTOQUE_ATUAL]]>=SUM(AVERAGE(_xlfn.XLOOKUP(Tabela4[[#This Row],[SKU]],'VENDA MES'!A:A,'VENDA MES'!B:B,0,0),_xlfn.XLOOKUP(Tabela4[[#This Row],[SKU]],'VENDA MES'!E:E,'VENDA MES'!F:F,0,0)),STDEV(_xlfn.XLOOKUP(Tabela4[[#This Row],[SKU]],'VENDA MES'!A:A,'VENDA MES'!B:B,0,0),_xlfn.XLOOKUP(Tabela4[[#This Row],[SKU]],'VENDA MES'!E:E,'VENDA MES'!F:F,0,0))),"OVER",IF(Tabela4[[#This Row],[SKU]]<=AVERAGE(_xlfn.XLOOKUP(Tabela4[[#This Row],[SKU]],'VENDA MES'!A:A,'VENDA MES'!B:B,0,0),_xlfn.XLOOKUP(Tabela4[[#This Row],[SKU]],'VENDA MES'!E:E,'VENDA MES'!F:F,0,0))-STDEV(_xlfn.XLOOKUP(Tabela4[[#This Row],[SKU]],'VENDA MES'!A:A,'VENDA MES'!B:B,0,0),_xlfn.XLOOKUP(Tabela4[[#This Row],[SKU]],'VENDA MES'!E:E,'VENDA MES'!F:F,0,0)),"OUT","IDEAL")) -> OVER | N8: =IF('ESTOQUE NOVEMBRO'!$E8>0,"Novembro","outubro") -> outubro | O8: 45597
A9: SKU0008 | B9: Fone de Ouvido Bluetooth | C9: =3.09*3*7 -> 64.89 | D9: =_xlfn.XLOOKUP(Tabela4[[#This Row],[SKU]],'ESTOQUE OUTUBRO'!A:A,'ESTOQUE OUTUBRO'!F:F,,0)-_xlfn.XLOOKUP(Tabela4[[#This Row],[SKU]],'VENDA MES'!E:E,'VENDA MES'!F:F,0,0) -> 141 | E9: =IF(D9<=0,(L9 * 2.5) - D9,IF(AND(Tabela4[[#This Row],[ESTOQUE_INICIAL]]<=Tabela4[[#This Row],[PONTO_DE_REPOSICAO]],Tabela4[[#This Row],[ESTOQUE_INICIAL]]>0),L9*1.5,D9*0)) -> 0 | F9: =SUM(E9,D9) -> 141 | G9: 24 | H9: 48 | I9: Eletrônicos | J9: ='ESTOQUE NOVEMBRO'!$D9*'ESTOQUE NOVEMBRO'!$G9+'ESTOQUE NOVEMBRO'!$E9*'ESTOQUE NOVEMBRO'!$H9 -> 3384 | K9: =_xlfn.XLOOKUP(A9,MEDIDAS!A:A,MEDIDAS!D:D,,0)*5 -> 6.1111111 | L9: =SUM(K9,_xlfn.XLOOKUP(A9,MEDIDAS!A:A,MEDIDAS!D:D,,0)*5) -> 12.222222 | M9: =IF(Tabela4[[#This Row],[ESTOQUE_ATUAL]]>=SUM(AVERAGE(_xlfn.XLOOKUP(Tabela4[[#This Row],[SKU]],'VENDA MES'!A:A,'VENDA MES'!B:B,0,0),_xlfn.XLOOKUP(Tabela4[[#This Row],[SKU]],'VENDA MES'!E:E,'VENDA MES'!F:F,0,0)),STDEV(_xlfn.XLOOKUP(Tabela4[[#This Row],[SKU]],'VENDA MES'!A:A,'VENDA MES'!B:B,0,0),_xlfn.XLOOKUP(Tabela4[[#This Row],[SKU]],'VENDA MES'!E:E,'VENDA MES'!F:F,0,0))),"OVER",IF(Tabela4[[#This Row],[SKU]]<=AVERAGE(_xlfn.XLOOKUP(Tabela4[[#This Row],[SKU]],'VENDA MES'!A:A,'VENDA MES'!B:B,0,0),_xlfn.XLOOKUP(Tabela4[[#This Row],[SKU]],'VENDA MES'!E:E,'VENDA MES'!F:F,0,0))-STDEV(_xlfn.XLOOKUP(Tabela4[[#This Row],[SKU]],'VENDA MES'!A:A,'VENDA MES'!B:B,0,0),_xlfn.XLOOKUP(Tabela4[[#This Row],[SKU]],'VENDA MES'!E:E,'VENDA MES'!F:F,0,0)),"OUT","IDEAL")) -> OVER | N9: =IF('ESTOQUE NOVEMBRO'!$E9>0,"Novembro","outubro") -> outubro | O9: 45597
A10: SKU0009 | B10: Fone de Ouvido Bluetooth | C10: =3.09*3*7 -> 64.89 | D10: =_xlfn.XLOOKUP(Tabela4[[#This Row],[SKU]],'ESTOQUE OUTUBRO'!A:A,'ESTOQUE OUTUBRO'!F:F,,0)-_xlfn.XLOOKUP(Tabela4[[#This Row],[SKU]],'VENDA MES'!E:E,'VENDA MES'!F:F,0,0) -> 110.2 | E10: =IF(D10<=0,(L10 * 2.5) - D10,IF(AND(Tabela4[[#This Row],[ESTOQUE_INICIAL]]<=Tabela4[[#This Row],[PONTO_DE_REPOSICAO]],Tabela4[[#This Row],[ESTOQUE_INICIAL]]>0),L10*1.5,D10*0)) -> 0 | F10: =SUM(E10,D10) -> 110.2 | G10: 24 | H10: 48 | I10: Eletrônicos | J10: ='ESTOQUE NOVEMBRO'!$D10*'ESTOQUE NOVEMBRO'!$G10+'ESTOQUE NOVEMBRO'!$E10*'ESTOQUE NOVEMBRO'!$H10 -> 2644.8 | K10: =_xlfn.XLOOKUP(A10,MEDIDAS!A:A,MEDIDAS!D:D,,0)*5 -> 6.7222222 | L10: =SUM(K10,_xlfn.XLOOKUP(A10,MEDIDAS!A:A,MEDIDAS!D:D,,0)*5) -> 13.444444 | M10: =IF(Tabela4[[#This Row],[ESTOQUE_ATUAL]]>=SUM(AVERAGE(_xlfn.XLOOKUP(Tabela4[[#This Row],[SKU]],'VENDA MES'!A:A,'VENDA MES'!B:B,0,0),_xlfn.XLOOKUP(Tabela4[[#This Row],[SKU]],'VENDA MES'!E:E,'VENDA MES'!F:F,0,0)),STDEV(_xlfn.XLOOKUP(Tabela4[[#This Row],[SKU]],'VENDA MES'!A:A,'VENDA MES'!B:B,0,0),_xlfn.XLOOKUP(Tabela4[[#This Row],[SKU]],'VENDA MES'!E:E,'VENDA MES'!F:F,0,0))),"OVER",IF(Tabela4[[#This Row],[SKU]]<=AVERAGE(_xlfn.XLOOKUP(Tabela4[[#This Row],[SKU]],'VENDA MES'!A:A,'VENDA MES'!B:B,0,0),_xlfn.XLOOKUP(Tabela4[[#This Row],[SKU]],'VENDA MES'!E:E,'VENDA MES'!F:F,0,0))-STDEV(_xlfn.XLOOKUP(Tabela4[[#This Row],[SKU]],'VENDA MES'!A:A,'VENDA MES'!B:B,0,0),_xlfn.XLOOKUP(Tabela4[[#This Row],[SKU]],'VENDA MES'!E:E,'VENDA MES'!F:F,0,0)),"OUT","IDEAL")) -> OVER | N10: =IF('ESTOQUE NOVEMBRO'!$E10>0,"Novembro","outubro") -> outubro | O10: 45597
A11: SKU0010 | B11: Fone de Ouvido Bluetooth | C11: =3.09*3*7 -> 64.89 | D11: =_xlfn.XLOOKUP(Tabela4[[#This Row],[SKU]],'ESTOQUE OUTUBRO'!A:A,'ESTOQUE OUTUBRO'!F:F,,0)-_xlfn.XLOOKUP(Tabela4[[#This Row],[SKU]],'VENDA MES'!E:E,'VENDA MES'!F:F,0,0) -> 68.4 | E11: =IF(D11<=0,(L11 * 2.5) - D11,IF(AND(Tabela4[[#This Row],[ESTOQUE_INICIAL]]<=Tabela4[[#This Row],[PONTO_DE_REPOSICAO]],Tabela4[[#This Row],[ESTOQUE_INICIAL]]>0),L11*1.5,D11*0)) -> 0 | F11: =SUM(E11,D11) -> 68.4 | G11: 24 | H11: 48 | I11: Eletrônicos | J11: ='ESTOQUE NOVEMBRO'!$D11*'ESTOQUE NOVEMBRO'!$G11+'ESTOQUE NOVEMBRO'!$E11*'ESTOQUE NOVEMBRO'!$H11 -> 1641.6 | K11: =_xlfn.XLOOKUP(A11,MEDIDAS!A:A,MEDIDAS!D:D,,0)*5 -> 8.6111111 | L11: =SUM(K11,_xlfn.XLOOKUP(A11,MEDIDAS!A:A,MEDIDAS!D:D,,0)*5) -> 17.222222 | M11: =IF(Tabela4[[#This Row],[ESTOQUE_ATUAL]]>=SUM(AVERAGE(_xlfn.XLOOKUP(Tabela4[[#This Row],[SKU]],'VENDA MES'!A:A,'VENDA MES'!B:B,0,0),_xlfn.XLOOKUP(Tabela4[[#This Row],[SKU]],'VENDA MES'!E:E,'VENDA MES'!F:F,0,0)),STDEV(_xlfn.XLOOKUP(Tabela4[[#This Row],[SKU]],'VENDA MES'!A:A,'VENDA MES'!B:B,0,0),_xlfn.XLOOKUP(Tabela4[[#This Row],[SKU]],'VENDA MES'!E:E,'VENDA MES'!F:F,0,0))),"OVER",IF(Tabela4[[#This Row],[SKU]]<=AVERAGE(_xlfn.XLOOKUP(Tabela4[[#This Row],[SKU]],'VENDA MES'!A:A,'VENDA MES'!B:B,0,0),_xlfn.XLOOKUP(Tabela4[[#This Row],[SKU]],'VENDA MES'!E:E,'VENDA MES'!F:F,0,0))-STDEV(_xlfn.XLOOKUP(Tabela4[[#This Row],[SKU]],'VENDA MES'!A:A,'VENDA MES'!B:B,0,0),_xlfn.XLOOKUP(Tabela4[[#This Row],[SKU]],'VENDA MES'!E:E,'VENDA MES'!F:F,0,0)),"OUT","IDEAL")) -> IDEAL | N11: =IF('ESTOQUE NOVEMBRO'!$E11>0,"Novembro","outubro") -> outubro | O11: 45597
A12: SKU0011 | B12: Capa para Celular | C12: =3.09*3*7 -> 64.89 | D12: =_xlfn.XLOOKUP(Tabela4[[#This Row],[SKU]],'ESTOQUE OUTUBRO'!A:A,'ESTOQUE OUTUBRO'!F:F,,0)-_xlfn.XLOOKUP(Tabela4[[#This Row],[SKU]],'VENDA MES'!E:E,'VENDA MES'!F:F,0,0) -> 43.8 | E12: =IF(D12<=0,(L12 * 2.5) - D12,IF(AND(Tabela4[[#This Row],[ESTOQUE_INICIAL]]<=Tabela4[[#This Row],[PONTO_DE_REPOSICAO]],Tabela4[[#This Row],[ESTOQUE_INICIAL]]>0),L12*1.5,D12*0)) -> 0 | F12: =SUM(E12,D12) -> 43.8 | G12: 5 | H12: 10 | I12: Acessórios | J12: ='ESTOQUE NOVEMBRO'!$D12*'ESTOQUE NOVEMBRO'!$G12+'ESTOQUE NOVEMBRO'!$E12*'ESTOQUE NOVEMBRO'!$H12 -> 219 | K12: =_xlfn.XLOOKUP(A12,MEDIDAS!A:A,MEDIDAS!D:D,,0)*5 -> 6.0555556 | L12: =SUM(K12,_xlfn.XLOOKUP(A12,MEDIDAS!A:A,MEDIDAS!D:D,,0)*5) -> 12.111111 | M12: =IF(Tabela4[[#This Row],[ESTOQUE_ATUAL]]>=SUM(AVERAGE(_xlfn.XLOOKUP(Tabela4[[#This Row],[SKU]],'VENDA MES'!A:A,'VENDA MES'!B:B,0,0),_xlfn.XLOOKUP(Tabela4[[#This Row],[SKU]],'VENDA MES'!E:E,'VENDA MES'!F:F,0,0)),STDEV(_xlfn.XLOOKUP(Tabela4[[#This Row],[SKU]],'VENDA MES'!A:A,'VENDA MES'!B:B,0,0),_xlfn.XLOOKUP(Tabela4[[#This Row],[SKU]],'VENDA MES'!E:E,'VENDA MES'!F:F,0,0))),"OVER",IF(Tabela4[[#This Row],[SKU]]<=AVERAGE(_xlfn.XLOOKUP(Tabela4[[#This Row],[SKU]],'VENDA MES'!A:A,'VENDA MES'!B:B,0,0),_xlfn.XLOOKUP(Tabela4[[#This Row],[SKU]],'VENDA MES'!E:E,'VENDA MES'!F:F,0,0))-STDEV(_xlfn.XLOOKUP(Tabela4[[#This Row],[SKU]],'VENDA MES'!A:A,'VENDA MES'!B:B,0,0),_xlfn.XLOOKUP(Tabela4[[#This Row],[SKU]],'VENDA MES'!E:E,'VENDA MES'!F:F,0,0)),"OUT","IDEAL")) -> OVER | N12: =IF('ESTOQUE NOVEMBRO'!$E12>0,"Novembro","outubro") -> outubro | O12: 45597
A13: SKU0012 | B13: Capa para Celular | C13: =3.09*3*7 -> 64.89 | D13: =_xlfn.XLOOKUP(Tabela4[[#This Row],[SKU]],'ESTOQUE OUTUBRO'!A:A,'ESTOQUE OUTUBRO'!F:F,,0)-_xlfn.XLOOKUP(Tabela4[[#This Row],[SKU]],'VENDA MES'!E:E,'VENDA MES'!F:F,0,0) -> 68.6 | E13: =IF(D13<=0,(L13 * 2.5) - D13,IF(AND(Tabela4[[#This Row],[ESTOQUE_INICIAL]]<=Tabela4[[#This Row],[PONTO_DE_REPOSICAO]],Tabela4[[#This Row],[ESTOQUE_INICIAL]]>0),L13*1.5,D13*0)) -> 0 | F13: =SUM(E13,D13) -> 68.6 | G13: 5 | H13: 10 | I13: Acessórios | J13: ='ESTOQUE NOVEMBRO'!$D13*'ESTOQUE NOVEMBRO'!$G13+'ESTOQUE NOVEMBRO'!$E13*'ESTOQUE NOVEMBRO'!$H13 -> 343 | K13: =_xlfn.XLOOKUP(A13,MEDIDAS!A:A,MEDIDAS!D:D,,0)*5 -> 4.4444444 | L13: =SUM(K13,_xlfn.XLOOKUP(A13,MEDIDAS!A:A,MEDIDAS!D:D,,0)*5) -> 8.8888889 | M13: =IF(Tabela4[[#This Row],[ESTOQUE_ATUAL]]>=SUM(AVERAGE(_xlfn.XLOOKUP(Tabela4[[#This Row],[SKU]],'VENDA MES'!A:A,'VENDA MES'!B:B,0,0),_xlfn.XLOOKUP(Tabela4[[#This Row],[SKU]],'VENDA MES'!E:E,'VENDA MES'!F:F,0,0)),STDEV(_xlfn.XLOOKUP(Tabela4[[#This Row],[SKU]],'VENDA MES'!A:A,'VENDA MES'!B:B,0,0),_xlfn.XLOOKUP(Tabela4[[#This Row],[SKU]],'VENDA MES'!E:E,'VENDA MES'!F:F,0,0))),"OVER",IF(Tabela4[[#This Row],[SKU]]<=AVERAGE(_xlfn.XLOOKUP(Tabela4[[#This Row],[SKU]],'VENDA MES'!A:A,'VENDA MES'!B:B,0,0),_xlfn.XLOOKUP(Tabela4[[#This Row],[SKU]],'VENDA MES'!E:E,'VENDA MES'!F:F,0,0))-STDEV(_xlfn.XLOOKUP(Tabela4[[#This Row],[SKU]],'VENDA MES'!A:A,'VENDA MES'!B:B,0,0),_xlfn.XLOOKUP(Tabela4[[#This Row],[SKU]],'VENDA MES'!E:E,'VENDA MES'!F:F,0,0)),"OUT","IDEAL")) -> OVER | N13: =IF('ESTOQUE NOVEMBRO'!$E13>0,"Novembro","outubro") -> outubro | O13: 45597
